DEBUG 2025-03-18 21:08:36,041 base Exception while resolving variable 'seo_title' in template 'blog/blog_main.html'.
Traceback (most recent call last):
  File "/home/igor/venv/lib/python3.10/site-packages/django/template/base.py", line 880, in _resolve_lookup
    current = current[bit]
  File "/home/igor/venv/lib/python3.10/site-packages/django/template/context.py", line 83, in __getitem__
    raise KeyError(key)
KeyError: 'seo_title'

During handling of the above exception, another exception occurred:

Traceback (most recent call last):
  File "/home/igor/venv/lib/python3.10/site-packages/django/template/base.py", line 886, in _resolve_lookup
    if isinstance(current, BaseContext) and getattr(
AttributeError: type object 'RequestContext' has no attribute 'seo_title'

During handling of the above exception, another exception occurred:

Traceback (most recent call last):
  File "/home/igor/venv/lib/python3.10/site-packages/django/template/base.py", line 896, in _resolve_lookup
    current = current[int(bit)]
ValueError: invalid literal for int() with base 10: 'seo_title'

During handling of the above exception, another exception occurred:

Traceback (most recent call last):
  File "/home/igor/venv/lib/python3.10/site-packages/django/template/base.py", line 903, in _resolve_lookup
    raise VariableDoesNotExist(
django.template.base.VariableDoesNotExist: Failed lookup for key [seo_title] in [{'True': True, 'False': False, 'None': None}, {'csrf_token': <SimpleLazyObject: <function csrf.<locals>._get_val at 0x7f94d9f3e4d0>>, 'request': <WSGIRequest: GET '/blog/'>, 'user': <SimpleLazyObject: <function AuthenticationMiddleware.process_request.<locals>.<lambda> at 0x7f94d9174d30>>, 'perms': PermWrapper(<SimpleLazyObject: <function AuthenticationMiddleware.process_request.<locals>.<lambda> at 0x7f94d9174d30>>), 'messages': <FallbackStorage: request=<WSGIRequest: GET '/blog/'>>, 'DEFAULT_MESSAGE_LEVELS': {'DEBUG': 10, 'INFO': 20, 'SUCCESS': 25, 'WARNING': 30, 'ERROR': 40}, 'STATIC_URL': '/static/', 'menu': [{'title': 'О компании', 'url_name': 'about'}, {'title': 'Контакты', 'url_name': 'contacts'}, {'title': 'Продукция', 'url_name': 'catalog'}, {'title': 'Услуги', 'url_name': 'services', 'children': [{'title': 'Калькулятор доставки', 'url_name': 'delivery'}, {'title': 'Калькулятор бетона', 'url_name': 'concrete_calculator'}]}, {'title': 'Блог', 'url_name': 'blog'}], 'city_slug': 'mariupol', 'city_name': 'Мариуполь', 'cities': <QuerySet [<City: Донецк>, <City: Мариуполь>, <City: Луганск>]>, 'city_slugs': ['donetsk', 'mariupol', 'lugansk']}, {}, {'title': 'Блог', 'menu': [{'title': 'О компании', 'url_name': 'about'}, {'title': 'Контакты', 'url_name': 'contacts'}, {'title': 'Продукция', 'url_name': 'catalog'}, {'title': 'Блог', 'url_name': 'blog'}]}, {'block': <Block Node: title. Contents: [<TextNode: '\n            '>, <IfNode>, <TextNode: '\n        '>]>}]
DEBUG 2025-03-18 21:08:36,044 base Exception while resolving variable 'seo_description' in template 'blog/blog_main.html'.
Traceback (most recent call last):
  File "/home/igor/venv/lib/python3.10/site-packages/django/template/base.py", line 880, in _resolve_lookup
    current = current[bit]
  File "/home/igor/venv/lib/python3.10/site-packages/django/template/context.py", line 83, in __getitem__
    raise KeyError(key)
KeyError: 'seo_description'

During handling of the above exception, another exception occurred:

Traceback (most recent call last):
  File "/home/igor/venv/lib/python3.10/site-packages/django/template/base.py", line 886, in _resolve_lookup
    if isinstance(current, BaseContext) and getattr(
AttributeError: type object 'RequestContext' has no attribute 'seo_description'

During handling of the above exception, another exception occurred:

Traceback (most recent call last):
  File "/home/igor/venv/lib/python3.10/site-packages/django/template/base.py", line 896, in _resolve_lookup
    current = current[int(bit)]
ValueError: invalid literal for int() with base 10: 'seo_description'

During handling of the above exception, another exception occurred:

Traceback (most recent call last):
  File "/home/igor/venv/lib/python3.10/site-packages/django/template/base.py", line 903, in _resolve_lookup
    raise VariableDoesNotExist(
django.template.base.VariableDoesNotExist: Failed lookup for key [seo_description] in [{'True': True, 'False': False, 'None': None}, {'csrf_token': <SimpleLazyObject: <function csrf.<locals>._get_val at 0x7f94d9f3e4d0>>, 'request': <WSGIRequest: GET '/blog/'>, 'user': <SimpleLazyObject: <function AuthenticationMiddleware.process_request.<locals>.<lambda> at 0x7f94d9174d30>>, 'perms': PermWrapper(<SimpleLazyObject: <function AuthenticationMiddleware.process_request.<locals>.<lambda> at 0x7f94d9174d30>>), 'messages': <FallbackStorage: request=<WSGIRequest: GET '/blog/'>>, 'DEFAULT_MESSAGE_LEVELS': {'DEBUG': 10, 'INFO': 20, 'SUCCESS': 25, 'WARNING': 30, 'ERROR': 40}, 'STATIC_URL': '/static/', 'menu': [{'title': 'О компании', 'url_name': 'about'}, {'title': 'Контакты', 'url_name': 'contacts'}, {'title': 'Продукция', 'url_name': 'catalog'}, {'title': 'Услуги', 'url_name': 'services', 'children': [{'title': 'Калькулятор доставки', 'url_name': 'delivery'}, {'title': 'Калькулятор бетона', 'url_name': 'concrete_calculator'}]}, {'title': 'Блог', 'url_name': 'blog'}], 'city_slug': 'mariupol', 'city_name': 'Мариуполь', 'cities': <QuerySet [<City: Донецк>, <City: Мариуполь>, <City: Луганск>]>, 'city_slugs': ['donetsk', 'mariupol', 'lugansk']}, {}, {'title': 'Блог', 'menu': [{'title': 'О компании', 'url_name': 'about'}, {'title': 'Контакты', 'url_name': 'contacts'}, {'title': 'Продукция', 'url_name': 'catalog'}, {'title': 'Блог', 'url_name': 'blog'}]}]
DEBUG 2025-03-18 21:08:36,046 base Exception while resolving variable 'seo_description' in template 'blog/blog_main.html'.
Traceback (most recent call last):
  File "/home/igor/venv/lib/python3.10/site-packages/django/template/base.py", line 880, in _resolve_lookup
    current = current[bit]
  File "/home/igor/venv/lib/python3.10/site-packages/django/template/context.py", line 83, in __getitem__
    raise KeyError(key)
KeyError: 'seo_description'

During handling of the above exception, another exception occurred:

Traceback (most recent call last):
  File "/home/igor/venv/lib/python3.10/site-packages/django/template/base.py", line 886, in _resolve_lookup
    if isinstance(current, BaseContext) and getattr(
AttributeError: type object 'RequestContext' has no attribute 'seo_description'

During handling of the above exception, another exception occurred:

Traceback (most recent call last):
  File "/home/igor/venv/lib/python3.10/site-packages/django/template/base.py", line 896, in _resolve_lookup
    current = current[int(bit)]
ValueError: invalid literal for int() with base 10: 'seo_description'

During handling of the above exception, another exception occurred:

Traceback (most recent call last):
  File "/home/igor/venv/lib/python3.10/site-packages/django/template/base.py", line 903, in _resolve_lookup
    raise VariableDoesNotExist(
django.template.base.VariableDoesNotExist: Failed lookup for key [seo_description] in [{'True': True, 'False': False, 'None': None}, {'csrf_token': <SimpleLazyObject: <function csrf.<locals>._get_val at 0x7f94d9f3e4d0>>, 'request': <WSGIRequest: GET '/blog/'>, 'user': <SimpleLazyObject: <function AuthenticationMiddleware.process_request.<locals>.<lambda> at 0x7f94d9174d30>>, 'perms': PermWrapper(<SimpleLazyObject: <function AuthenticationMiddleware.process_request.<locals>.<lambda> at 0x7f94d9174d30>>), 'messages': <FallbackStorage: request=<WSGIRequest: GET '/blog/'>>, 'DEFAULT_MESSAGE_LEVELS': {'DEBUG': 10, 'INFO': 20, 'SUCCESS': 25, 'WARNING': 30, 'ERROR': 40}, 'STATIC_URL': '/static/', 'menu': [{'title': 'О компании', 'url_name': 'about'}, {'title': 'Контакты', 'url_name': 'contacts'}, {'title': 'Продукция', 'url_name': 'catalog'}, {'title': 'Услуги', 'url_name': 'services', 'children': [{'title': 'Калькулятор доставки', 'url_name': 'delivery'}, {'title': 'Калькулятор бетона', 'url_name': 'concrete_calculator'}]}, {'title': 'Блог', 'url_name': 'blog'}], 'city_slug': 'mariupol', 'city_name': 'Мариуполь', 'cities': <QuerySet [<City: Донецк>, <City: Мариуполь>, <City: Луганск>]>, 'city_slugs': ['donetsk', 'mariupol', 'lugansk']}, {}, {'title': 'Блог', 'menu': [{'title': 'О компании', 'url_name': 'about'}, {'title': 'Контакты', 'url_name': 'contacts'}, {'title': 'Продукция', 'url_name': 'catalog'}, {'title': 'Блог', 'url_name': 'blog'}]}]
DEBUG 2025-03-18 21:08:36,047 base Exception while resolving variable 'seo_keywords' in template 'blog/blog_main.html'.
Traceback (most recent call last):
  File "/home/igor/venv/lib/python3.10/site-packages/django/template/base.py", line 880, in _resolve_lookup
    current = current[bit]
  File "/home/igor/venv/lib/python3.10/site-packages/django/template/context.py", line 83, in __getitem__
    raise KeyError(key)
KeyError: 'seo_keywords'

During handling of the above exception, another exception occurred:

Traceback (most recent call last):
  File "/home/igor/venv/lib/python3.10/site-packages/django/template/base.py", line 886, in _resolve_lookup
    if isinstance(current, BaseContext) and getattr(
AttributeError: type object 'RequestContext' has no attribute 'seo_keywords'

During handling of the above exception, another exception occurred:

Traceback (most recent call last):
  File "/home/igor/venv/lib/python3.10/site-packages/django/template/base.py", line 896, in _resolve_lookup
    current = current[int(bit)]
ValueError: invalid literal for int() with base 10: 'seo_keywords'

During handling of the above exception, another exception occurred:

Traceback (most recent call last):
  File "/home/igor/venv/lib/python3.10/site-packages/django/template/base.py", line 903, in _resolve_lookup
    raise VariableDoesNotExist(
django.template.base.VariableDoesNotExist: Failed lookup for key [seo_keywords] in [{'True': True, 'False': False, 'None': None}, {'csrf_token': <SimpleLazyObject: <function csrf.<locals>._get_val at 0x7f94d9f3e4d0>>, 'request': <WSGIRequest: GET '/blog/'>, 'user': <SimpleLazyObject: <function AuthenticationMiddleware.process_request.<locals>.<lambda> at 0x7f94d9174d30>>, 'perms': PermWrapper(<SimpleLazyObject: <function AuthenticationMiddleware.process_request.<locals>.<lambda> at 0x7f94d9174d30>>), 'messages': <FallbackStorage: request=<WSGIRequest: GET '/blog/'>>, 'DEFAULT_MESSAGE_LEVELS': {'DEBUG': 10, 'INFO': 20, 'SUCCESS': 25, 'WARNING': 30, 'ERROR': 40}, 'STATIC_URL': '/static/', 'menu': [{'title': 'О компании', 'url_name': 'about'}, {'title': 'Контакты', 'url_name': 'contacts'}, {'title': 'Продукция', 'url_name': 'catalog'}, {'title': 'Услуги', 'url_name': 'services', 'children': [{'title': 'Калькулятор доставки', 'url_name': 'delivery'}, {'title': 'Калькулятор бетона', 'url_name': 'concrete_calculator'}]}, {'title': 'Блог', 'url_name': 'blog'}], 'city_slug': 'mariupol', 'city_name': 'Мариуполь', 'cities': <QuerySet [<City: Донецк>, <City: Мариуполь>, <City: Луганск>]>, 'city_slugs': ['donetsk', 'mariupol', 'lugansk']}, {}, {'title': 'Блог', 'menu': [{'title': 'О компании', 'url_name': 'about'}, {'title': 'Контакты', 'url_name': 'contacts'}, {'title': 'Продукция', 'url_name': 'catalog'}, {'title': 'Блог', 'url_name': 'blog'}]}]
DEBUG 2025-03-18 21:08:36,049 base Exception while resolving variable 'seo_keywords' in template 'blog/blog_main.html'.
Traceback (most recent call last):
  File "/home/igor/venv/lib/python3.10/site-packages/django/template/base.py", line 880, in _resolve_lookup
    current = current[bit]
  File "/home/igor/venv/lib/python3.10/site-packages/django/template/context.py", line 83, in __getitem__
    raise KeyError(key)
KeyError: 'seo_keywords'

During handling of the above exception, another exception occurred:

Traceback (most recent call last):
  File "/home/igor/venv/lib/python3.10/site-packages/django/template/base.py", line 886, in _resolve_lookup
    if isinstance(current, BaseContext) and getattr(
AttributeError: type object 'RequestContext' has no attribute 'seo_keywords'

During handling of the above exception, another exception occurred:

Traceback (most recent call last):
  File "/home/igor/venv/lib/python3.10/site-packages/django/template/base.py", line 896, in _resolve_lookup
    current = current[int(bit)]
ValueError: invalid literal for int() with base 10: 'seo_keywords'

During handling of the above exception, another exception occurred:

Traceback (most recent call last):
  File "/home/igor/venv/lib/python3.10/site-packages/django/template/base.py", line 903, in _resolve_lookup
    raise VariableDoesNotExist(
django.template.base.VariableDoesNotExist: Failed lookup for key [seo_keywords] in [{'True': True, 'False': False, 'None': None}, {'csrf_token': <SimpleLazyObject: <function csrf.<locals>._get_val at 0x7f94d9f3e4d0>>, 'request': <WSGIRequest: GET '/blog/'>, 'user': <SimpleLazyObject: <function AuthenticationMiddleware.process_request.<locals>.<lambda> at 0x7f94d9174d30>>, 'perms': PermWrapper(<SimpleLazyObject: <function AuthenticationMiddleware.process_request.<locals>.<lambda> at 0x7f94d9174d30>>), 'messages': <FallbackStorage: request=<WSGIRequest: GET '/blog/'>>, 'DEFAULT_MESSAGE_LEVELS': {'DEBUG': 10, 'INFO': 20, 'SUCCESS': 25, 'WARNING': 30, 'ERROR': 40}, 'STATIC_URL': '/static/', 'menu': [{'title': 'О компании', 'url_name': 'about'}, {'title': 'Контакты', 'url_name': 'contacts'}, {'title': 'Продукция', 'url_name': 'catalog'}, {'title': 'Услуги', 'url_name': 'services', 'children': [{'title': 'Калькулятор доставки', 'url_name': 'delivery'}, {'title': 'Калькулятор бетона', 'url_name': 'concrete_calculator'}]}, {'title': 'Блог', 'url_name': 'blog'}], 'city_slug': 'mariupol', 'city_name': 'Мариуполь', 'cities': <QuerySet [<City: Донецк>, <City: Мариуполь>, <City: Луганск>]>, 'city_slugs': ['donetsk', 'mariupol', 'lugansk']}, {}, {'title': 'Блог', 'menu': [{'title': 'О компании', 'url_name': 'about'}, {'title': 'Контакты', 'url_name': 'contacts'}, {'title': 'Продукция', 'url_name': 'catalog'}, {'title': 'Блог', 'url_name': 'blog'}]}]
DEBUG 2025-03-18 21:08:41,560 base Exception while resolving variable 'category_selected' in template 'good/products.html'.
Traceback (most recent call last):
  File "/home/igor/venv/lib/python3.10/site-packages/django/template/base.py", line 880, in _resolve_lookup
    current = current[bit]
  File "/home/igor/venv/lib/python3.10/site-packages/django/template/context.py", line 83, in __getitem__
    raise KeyError(key)
KeyError: 'category_selected'

During handling of the above exception, another exception occurred:

Traceback (most recent call last):
  File "/home/igor/venv/lib/python3.10/site-packages/django/template/base.py", line 886, in _resolve_lookup
    if isinstance(current, BaseContext) and getattr(
AttributeError: type object 'RequestContext' has no attribute 'category_selected'

During handling of the above exception, another exception occurred:

Traceback (most recent call last):
  File "/home/igor/venv/lib/python3.10/site-packages/django/template/base.py", line 896, in _resolve_lookup
    current = current[int(bit)]
ValueError: invalid literal for int() with base 10: 'category_selected'

During handling of the above exception, another exception occurred:

Traceback (most recent call last):
  File "/home/igor/venv/lib/python3.10/site-packages/django/template/base.py", line 903, in _resolve_lookup
    raise VariableDoesNotExist(
django.template.base.VariableDoesNotExist: Failed lookup for key [category_selected] in [{'True': True, 'False': False, 'None': None}, {'csrf_token': <SimpleLazyObject: '2p0U1hw43GNt8xc7qoD6WF6OdOyGxeK4rSiaseo9GNLKfA44B105VVMa4atxqo9X'>, 'request': <WSGIRequest: GET '/catalog/donetsk/'>, 'user': <SimpleLazyObject: <function AuthenticationMiddleware.process_request.<locals>.<lambda> at 0x7f94d902f5b0>>, 'perms': PermWrapper(<SimpleLazyObject: <function AuthenticationMiddleware.process_request.<locals>.<lambda> at 0x7f94d902f5b0>>), 'messages': <FallbackStorage: request=<WSGIRequest: GET '/catalog/donetsk/'>>, 'DEFAULT_MESSAGE_LEVELS': {'DEBUG': 10, 'INFO': 20, 'SUCCESS': 25, 'WARNING': 30, 'ERROR': 40}, 'STATIC_URL': '/static/', 'menu': [{'title': 'О компании', 'url_name': 'about'}, {'title': 'Контакты', 'url_name': 'contacts'}, {'title': 'Продукция', 'url_name': 'catalog'}, {'title': 'Услуги', 'url_name': 'services', 'children': [{'title': 'Калькулятор доставки', 'url_name': 'delivery'}, {'title': 'Калькулятор бетона', 'url_name': 'concrete_calculator'}]}, {'title': 'Блог', 'url_name': 'blog'}], 'city_slug': 'mariupol', 'city_name': 'Мариуполь', 'cities': <QuerySet [<City: Донецк>, <City: Мариуполь>, <City: Луганск>]>, 'city_slugs': ['donetsk', 'mariupol', 'lugansk']}, {}, {'title': 'Товарный каталог продукции ТД Ленинградский в ДНР: город Донецк', 'products': <QuerySet [<Product: Бетон М400>, <Product: Бетон М300>, <Product: Бетон М250>, <Product: Бетон М200>, <Product: Бетон М100>, <Product: Бетон М50>, <Product: Строительный песок>, <Product: Гранитный щебень 20-40>, <Product: Гранитный щебень 10-20>, <Product: Гранитный щебень 5-10>]>, 'seo_title': 'Товарный каталог продукции ТД Ленинградский в городе Донецк', 'seo_description': 'Бетон и нерудные материалы в ДНР, город Донецк от производителя | ТД Ленинградский', 'seo_keywords': 'купить бетон, продажа нерудных материалов, бетонный завод ТД Ленинградский', 'city_slug': 'donetsk', 'city_name': 'Донецк', 'breadcrumbs': [{'title': 'Главная', 'url': '/'}, {'title': 'Каталог Донецк', 'url': '/catalog/donetsk/'}]}, {'block': <Block Node: sidebar. Contents: [<TextNode: '\n    <div class="goods__s'>, <IncludeNode: template=<FilterExpression '"good/includes/sidebar.html"'>>, <TextNode: '\n'>]>}, {}]
DEBUG 2025-03-18 21:08:41,568 base Exception while resolving variable 'category_selected' in template 'good/products.html'.
Traceback (most recent call last):
  File "/home/igor/venv/lib/python3.10/site-packages/django/template/base.py", line 880, in _resolve_lookup
    current = current[bit]
  File "/home/igor/venv/lib/python3.10/site-packages/django/template/context.py", line 83, in __getitem__
    raise KeyError(key)
KeyError: 'category_selected'

During handling of the above exception, another exception occurred:

Traceback (most recent call last):
  File "/home/igor/venv/lib/python3.10/site-packages/django/template/base.py", line 886, in _resolve_lookup
    if isinstance(current, BaseContext) and getattr(
AttributeError: type object 'RequestContext' has no attribute 'category_selected'

During handling of the above exception, another exception occurred:

Traceback (most recent call last):
  File "/home/igor/venv/lib/python3.10/site-packages/django/template/base.py", line 896, in _resolve_lookup
    current = current[int(bit)]
ValueError: invalid literal for int() with base 10: 'category_selected'

During handling of the above exception, another exception occurred:

Traceback (most recent call last):
  File "/home/igor/venv/lib/python3.10/site-packages/django/template/base.py", line 903, in _resolve_lookup
    raise VariableDoesNotExist(
django.template.base.VariableDoesNotExist: Failed lookup for key [category_selected] in [{'True': True, 'False': False, 'None': None}, {'csrf_token': <SimpleLazyObject: '2p0U1hw43GNt8xc7qoD6WF6OdOyGxeK4rSiaseo9GNLKfA44B105VVMa4atxqo9X'>, 'request': <WSGIRequest: GET '/catalog/donetsk/'>, 'user': <SimpleLazyObject: <function AuthenticationMiddleware.process_request.<locals>.<lambda> at 0x7f94d902f5b0>>, 'perms': PermWrapper(<SimpleLazyObject: <function AuthenticationMiddleware.process_request.<locals>.<lambda> at 0x7f94d902f5b0>>), 'messages': <FallbackStorage: request=<WSGIRequest: GET '/catalog/donetsk/'>>, 'DEFAULT_MESSAGE_LEVELS': {'DEBUG': 10, 'INFO': 20, 'SUCCESS': 25, 'WARNING': 30, 'ERROR': 40}, 'STATIC_URL': '/static/', 'menu': [{'title': 'О компании', 'url_name': 'about'}, {'title': 'Контакты', 'url_name': 'contacts'}, {'title': 'Продукция', 'url_name': 'catalog'}, {'title': 'Услуги', 'url_name': 'services', 'children': [{'title': 'Калькулятор доставки', 'url_name': 'delivery'}, {'title': 'Калькулятор бетона', 'url_name': 'concrete_calculator'}]}, {'title': 'Блог', 'url_name': 'blog'}], 'city_slug': 'mariupol', 'city_name': 'Мариуполь', 'cities': <QuerySet [<City: Донецк>, <City: Мариуполь>, <City: Луганск>]>, 'city_slugs': ['donetsk', 'mariupol', 'lugansk']}, {}, {'title': 'Товарный каталог продукции ТД Ленинградский в ДНР: город Донецк', 'products': <QuerySet [<Product: Бетон М400>, <Product: Бетон М300>, <Product: Бетон М250>, <Product: Бетон М200>, <Product: Бетон М100>, <Product: Бетон М50>, <Product: Строительный песок>, <Product: Гранитный щебень 20-40>, <Product: Гранитный щебень 10-20>, <Product: Гранитный щебень 5-10>]>, 'seo_title': 'Товарный каталог продукции ТД Ленинградский в городе Донецк', 'seo_description': 'Бетон и нерудные материалы в ДНР, город Донецк от производителя | ТД Ленинградский', 'seo_keywords': 'купить бетон, продажа нерудных материалов, бетонный завод ТД Ленинградский', 'city_slug': 'donetsk', 'city_name': 'Донецк', 'breadcrumbs': [{'title': 'Главная', 'url': '/'}, {'title': 'Каталог Донецк', 'url': '/catalog/donetsk/'}]}, {'block': <Block Node: sidebar. Contents: [<TextNode: '\n    <div class="goods__s'>, <IncludeNode: template=<FilterExpression '"good/includes/sidebar.html"'>>, <TextNode: '\n'>]>}, {}]
DEBUG 2025-03-18 21:08:41,573 base Exception while resolving variable 'category_selected' in template 'good/products.html'.
Traceback (most recent call last):
  File "/home/igor/venv/lib/python3.10/site-packages/django/template/base.py", line 880, in _resolve_lookup
    current = current[bit]
  File "/home/igor/venv/lib/python3.10/site-packages/django/template/context.py", line 83, in __getitem__
    raise KeyError(key)
KeyError: 'category_selected'

During handling of the above exception, another exception occurred:

Traceback (most recent call last):
  File "/home/igor/venv/lib/python3.10/site-packages/django/template/base.py", line 886, in _resolve_lookup
    if isinstance(current, BaseContext) and getattr(
AttributeError: type object 'RequestContext' has no attribute 'category_selected'

During handling of the above exception, another exception occurred:

Traceback (most recent call last):
  File "/home/igor/venv/lib/python3.10/site-packages/django/template/base.py", line 896, in _resolve_lookup
    current = current[int(bit)]
ValueError: invalid literal for int() with base 10: 'category_selected'

During handling of the above exception, another exception occurred:

Traceback (most recent call last):
  File "/home/igor/venv/lib/python3.10/site-packages/django/template/base.py", line 903, in _resolve_lookup
    raise VariableDoesNotExist(
django.template.base.VariableDoesNotExist: Failed lookup for key [category_selected] in [{'True': True, 'False': False, 'None': None}, {'csrf_token': <SimpleLazyObject: '2p0U1hw43GNt8xc7qoD6WF6OdOyGxeK4rSiaseo9GNLKfA44B105VVMa4atxqo9X'>, 'request': <WSGIRequest: GET '/catalog/donetsk/'>, 'user': <SimpleLazyObject: <function AuthenticationMiddleware.process_request.<locals>.<lambda> at 0x7f94d902f5b0>>, 'perms': PermWrapper(<SimpleLazyObject: <function AuthenticationMiddleware.process_request.<locals>.<lambda> at 0x7f94d902f5b0>>), 'messages': <FallbackStorage: request=<WSGIRequest: GET '/catalog/donetsk/'>>, 'DEFAULT_MESSAGE_LEVELS': {'DEBUG': 10, 'INFO': 20, 'SUCCESS': 25, 'WARNING': 30, 'ERROR': 40}, 'STATIC_URL': '/static/', 'menu': [{'title': 'О компании', 'url_name': 'about'}, {'title': 'Контакты', 'url_name': 'contacts'}, {'title': 'Продукция', 'url_name': 'catalog'}, {'title': 'Услуги', 'url_name': 'services', 'children': [{'title': 'Калькулятор доставки', 'url_name': 'delivery'}, {'title': 'Калькулятор бетона', 'url_name': 'concrete_calculator'}]}, {'title': 'Блог', 'url_name': 'blog'}], 'city_slug': 'mariupol', 'city_name': 'Мариуполь', 'cities': <QuerySet [<City: Донецк>, <City: Мариуполь>, <City: Луганск>]>, 'city_slugs': ['donetsk', 'mariupol', 'lugansk']}, {}, {'title': 'Товарный каталог продукции ТД Ленинградский в ДНР: город Донецк', 'products': <QuerySet [<Product: Бетон М400>, <Product: Бетон М300>, <Product: Бетон М250>, <Product: Бетон М200>, <Product: Бетон М100>, <Product: Бетон М50>, <Product: Строительный песок>, <Product: Гранитный щебень 20-40>, <Product: Гранитный щебень 10-20>, <Product: Гранитный щебень 5-10>]>, 'seo_title': 'Товарный каталог продукции ТД Ленинградский в городе Донецк', 'seo_description': 'Бетон и нерудные материалы в ДНР, город Донецк от производителя | ТД Ленинградский', 'seo_keywords': 'купить бетон, продажа нерудных материалов, бетонный завод ТД Ленинградский', 'city_slug': 'donetsk', 'city_name': 'Донецк', 'breadcrumbs': [{'title': 'Главная', 'url': '/'}, {'title': 'Каталог Донецк', 'url': '/catalog/donetsk/'}]}, {'block': <Block Node: sidebar. Contents: [<TextNode: '\n    <div class="goods__s'>, <IncludeNode: template=<FilterExpression '"good/includes/sidebar.html"'>>, <TextNode: '\n'>]>}, {}]
DEBUG 2025-03-18 21:08:41,594 base Exception while resolving variable 'category_selected' in template 'good/products.html'.
Traceback (most recent call last):
  File "/home/igor/venv/lib/python3.10/site-packages/django/template/base.py", line 880, in _resolve_lookup
    current = current[bit]
  File "/home/igor/venv/lib/python3.10/site-packages/django/template/context.py", line 83, in __getitem__
    raise KeyError(key)
KeyError: 'category_selected'

During handling of the above exception, another exception occurred:

Traceback (most recent call last):
  File "/home/igor/venv/lib/python3.10/site-packages/django/template/base.py", line 886, in _resolve_lookup
    if isinstance(current, BaseContext) and getattr(
AttributeError: type object 'RequestContext' has no attribute 'category_selected'

During handling of the above exception, another exception occurred:

Traceback (most recent call last):
  File "/home/igor/venv/lib/python3.10/site-packages/django/template/base.py", line 896, in _resolve_lookup
    current = current[int(bit)]
ValueError: invalid literal for int() with base 10: 'category_selected'

During handling of the above exception, another exception occurred:

Traceback (most recent call last):
  File "/home/igor/venv/lib/python3.10/site-packages/django/template/base.py", line 903, in _resolve_lookup
    raise VariableDoesNotExist(
django.template.base.VariableDoesNotExist: Failed lookup for key [category_selected] in [{'True': True, 'False': False, 'None': None}, {'csrf_token': <SimpleLazyObject: '2p0U1hw43GNt8xc7qoD6WF6OdOyGxeK4rSiaseo9GNLKfA44B105VVMa4atxqo9X'>, 'request': <WSGIRequest: GET '/catalog/donetsk/'>, 'user': <SimpleLazyObject: <function AuthenticationMiddleware.process_request.<locals>.<lambda> at 0x7f94d902f5b0>>, 'perms': PermWrapper(<SimpleLazyObject: <function AuthenticationMiddleware.process_request.<locals>.<lambda> at 0x7f94d902f5b0>>), 'messages': <FallbackStorage: request=<WSGIRequest: GET '/catalog/donetsk/'>>, 'DEFAULT_MESSAGE_LEVELS': {'DEBUG': 10, 'INFO': 20, 'SUCCESS': 25, 'WARNING': 30, 'ERROR': 40}, 'STATIC_URL': '/static/', 'menu': [{'title': 'О компании', 'url_name': 'about'}, {'title': 'Контакты', 'url_name': 'contacts'}, {'title': 'Продукция', 'url_name': 'catalog'}, {'title': 'Услуги', 'url_name': 'services', 'children': [{'title': 'Калькулятор доставки', 'url_name': 'delivery'}, {'title': 'Калькулятор бетона', 'url_name': 'concrete_calculator'}]}, {'title': 'Блог', 'url_name': 'blog'}], 'city_slug': 'mariupol', 'city_name': 'Мариуполь', 'cities': <QuerySet [<City: Донецк>, <City: Мариуполь>, <City: Луганск>]>, 'city_slugs': ['donetsk', 'mariupol', 'lugansk']}, {}, {'title': 'Товарный каталог продукции ТД Ленинградский в ДНР: город Донецк', 'products': <QuerySet [<Product: Бетон М400>, <Product: Бетон М300>, <Product: Бетон М250>, <Product: Бетон М200>, <Product: Бетон М100>, <Product: Бетон М50>, <Product: Строительный песок>, <Product: Гранитный щебень 20-40>, <Product: Гранитный щебень 10-20>, <Product: Гранитный щебень 5-10>]>, 'seo_title': 'Товарный каталог продукции ТД Ленинградский в городе Донецк', 'seo_description': 'Бетон и нерудные материалы в ДНР, город Донецк от производителя | ТД Ленинградский', 'seo_keywords': 'купить бетон, продажа нерудных материалов, бетонный завод ТД Ленинградский', 'city_slug': 'donetsk', 'city_name': 'Донецк', 'breadcrumbs': [{'title': 'Главная', 'url': '/'}, {'title': 'Каталог Донецк', 'url': '/catalog/donetsk/'}]}, {'block': <Block Node: content. Contents: [<TextNode: '\n    <div class="goods__s'>, <IncludeNode: template=<FilterExpression "'good/includes/breadcrumbs.html'">>, <TextNode: '\n    <!-- Конец хлебных к'>, <IncludeNode: template=<FilterExpression '"good/includes/mobile_menu.html"'>>, <TextNode: '\n        <h1>'>, <Variable Node: title>, <TextNode: '</h1>\n        '>, <IfNode>, <TextNode: '\n\n        <div class="pro'>, <IfNode>, <TextNode: '\n        </div>\n\n\n       '>, <IfNode>, <TextNode: '\n\n    </div>\n    </div>\n'>]>}, {}]
DEBUG 2025-03-18 21:08:41,600 base Exception while resolving variable 'category_selected' in template 'good/products.html'.
Traceback (most recent call last):
  File "/home/igor/venv/lib/python3.10/site-packages/django/template/base.py", line 880, in _resolve_lookup
    current = current[bit]
  File "/home/igor/venv/lib/python3.10/site-packages/django/template/context.py", line 83, in __getitem__
    raise KeyError(key)
KeyError: 'category_selected'

During handling of the above exception, another exception occurred:

Traceback (most recent call last):
  File "/home/igor/venv/lib/python3.10/site-packages/django/template/base.py", line 886, in _resolve_lookup
    if isinstance(current, BaseContext) and getattr(
AttributeError: type object 'RequestContext' has no attribute 'category_selected'

During handling of the above exception, another exception occurred:

Traceback (most recent call last):
  File "/home/igor/venv/lib/python3.10/site-packages/django/template/base.py", line 896, in _resolve_lookup
    current = current[int(bit)]
ValueError: invalid literal for int() with base 10: 'category_selected'

During handling of the above exception, another exception occurred:

Traceback (most recent call last):
  File "/home/igor/venv/lib/python3.10/site-packages/django/template/base.py", line 903, in _resolve_lookup
    raise VariableDoesNotExist(
django.template.base.VariableDoesNotExist: Failed lookup for key [category_selected] in [{'True': True, 'False': False, 'None': None}, {'csrf_token': <SimpleLazyObject: '2p0U1hw43GNt8xc7qoD6WF6OdOyGxeK4rSiaseo9GNLKfA44B105VVMa4atxqo9X'>, 'request': <WSGIRequest: GET '/catalog/donetsk/'>, 'user': <SimpleLazyObject: <function AuthenticationMiddleware.process_request.<locals>.<lambda> at 0x7f94d902f5b0>>, 'perms': PermWrapper(<SimpleLazyObject: <function AuthenticationMiddleware.process_request.<locals>.<lambda> at 0x7f94d902f5b0>>), 'messages': <FallbackStorage: request=<WSGIRequest: GET '/catalog/donetsk/'>>, 'DEFAULT_MESSAGE_LEVELS': {'DEBUG': 10, 'INFO': 20, 'SUCCESS': 25, 'WARNING': 30, 'ERROR': 40}, 'STATIC_URL': '/static/', 'menu': [{'title': 'О компании', 'url_name': 'about'}, {'title': 'Контакты', 'url_name': 'contacts'}, {'title': 'Продукция', 'url_name': 'catalog'}, {'title': 'Услуги', 'url_name': 'services', 'children': [{'title': 'Калькулятор доставки', 'url_name': 'delivery'}, {'title': 'Калькулятор бетона', 'url_name': 'concrete_calculator'}]}, {'title': 'Блог', 'url_name': 'blog'}], 'city_slug': 'mariupol', 'city_name': 'Мариуполь', 'cities': <QuerySet [<City: Донецк>, <City: Мариуполь>, <City: Луганск>]>, 'city_slugs': ['donetsk', 'mariupol', 'lugansk']}, {}, {'title': 'Товарный каталог продукции ТД Ленинградский в ДНР: город Донецк', 'products': <QuerySet [<Product: Бетон М400>, <Product: Бетон М300>, <Product: Бетон М250>, <Product: Бетон М200>, <Product: Бетон М100>, <Product: Бетон М50>, <Product: Строительный песок>, <Product: Гранитный щебень 20-40>, <Product: Гранитный щебень 10-20>, <Product: Гранитный щебень 5-10>]>, 'seo_title': 'Товарный каталог продукции ТД Ленинградский в городе Донецк', 'seo_description': 'Бетон и нерудные материалы в ДНР, город Донецк от производителя | ТД Ленинградский', 'seo_keywords': 'купить бетон, продажа нерудных материалов, бетонный завод ТД Ленинградский', 'city_slug': 'donetsk', 'city_name': 'Донецк', 'breadcrumbs': [{'title': 'Главная', 'url': '/'}, {'title': 'Каталог Донецк', 'url': '/catalog/donetsk/'}]}, {'block': <Block Node: content. Contents: [<TextNode: '\n    <div class="goods__s'>, <IncludeNode: template=<FilterExpression "'good/includes/breadcrumbs.html'">>, <TextNode: '\n    <!-- Конец хлебных к'>, <IncludeNode: template=<FilterExpression '"good/includes/mobile_menu.html"'>>, <TextNode: '\n        <h1>'>, <Variable Node: title>, <TextNode: '</h1>\n        '>, <IfNode>, <TextNode: '\n\n        <div class="pro'>, <IfNode>, <TextNode: '\n        </div>\n\n\n       '>, <IfNode>, <TextNode: '\n\n    </div>\n    </div>\n'>]>}, {}]
DEBUG 2025-03-18 21:08:41,604 base Exception while resolving variable 'category_selected' in template 'good/products.html'.
Traceback (most recent call last):
  File "/home/igor/venv/lib/python3.10/site-packages/django/template/base.py", line 880, in _resolve_lookup
    current = current[bit]
  File "/home/igor/venv/lib/python3.10/site-packages/django/template/context.py", line 83, in __getitem__
    raise KeyError(key)
KeyError: 'category_selected'

During handling of the above exception, another exception occurred:

Traceback (most recent call last):
  File "/home/igor/venv/lib/python3.10/site-packages/django/template/base.py", line 886, in _resolve_lookup
    if isinstance(current, BaseContext) and getattr(
AttributeError: type object 'RequestContext' has no attribute 'category_selected'

During handling of the above exception, another exception occurred:

Traceback (most recent call last):
  File "/home/igor/venv/lib/python3.10/site-packages/django/template/base.py", line 896, in _resolve_lookup
    current = current[int(bit)]
ValueError: invalid literal for int() with base 10: 'category_selected'

During handling of the above exception, another exception occurred:

Traceback (most recent call last):
  File "/home/igor/venv/lib/python3.10/site-packages/django/template/base.py", line 903, in _resolve_lookup
    raise VariableDoesNotExist(
django.template.base.VariableDoesNotExist: Failed lookup for key [category_selected] in [{'True': True, 'False': False, 'None': None}, {'csrf_token': <SimpleLazyObject: '2p0U1hw43GNt8xc7qoD6WF6OdOyGxeK4rSiaseo9GNLKfA44B105VVMa4atxqo9X'>, 'request': <WSGIRequest: GET '/catalog/donetsk/'>, 'user': <SimpleLazyObject: <function AuthenticationMiddleware.process_request.<locals>.<lambda> at 0x7f94d902f5b0>>, 'perms': PermWrapper(<SimpleLazyObject: <function AuthenticationMiddleware.process_request.<locals>.<lambda> at 0x7f94d902f5b0>>), 'messages': <FallbackStorage: request=<WSGIRequest: GET '/catalog/donetsk/'>>, 'DEFAULT_MESSAGE_LEVELS': {'DEBUG': 10, 'INFO': 20, 'SUCCESS': 25, 'WARNING': 30, 'ERROR': 40}, 'STATIC_URL': '/static/', 'menu': [{'title': 'О компании', 'url_name': 'about'}, {'title': 'Контакты', 'url_name': 'contacts'}, {'title': 'Продукция', 'url_name': 'catalog'}, {'title': 'Услуги', 'url_name': 'services', 'children': [{'title': 'Калькулятор доставки', 'url_name': 'delivery'}, {'title': 'Калькулятор бетона', 'url_name': 'concrete_calculator'}]}, {'title': 'Блог', 'url_name': 'blog'}], 'city_slug': 'mariupol', 'city_name': 'Мариуполь', 'cities': <QuerySet [<City: Донецк>, <City: Мариуполь>, <City: Луганск>]>, 'city_slugs': ['donetsk', 'mariupol', 'lugansk']}, {}, {'title': 'Товарный каталог продукции ТД Ленинградский в ДНР: город Донецк', 'products': <QuerySet [<Product: Бетон М400>, <Product: Бетон М300>, <Product: Бетон М250>, <Product: Бетон М200>, <Product: Бетон М100>, <Product: Бетон М50>, <Product: Строительный песок>, <Product: Гранитный щебень 20-40>, <Product: Гранитный щебень 10-20>, <Product: Гранитный щебень 5-10>]>, 'seo_title': 'Товарный каталог продукции ТД Ленинградский в городе Донецк', 'seo_description': 'Бетон и нерудные материалы в ДНР, город Донецк от производителя | ТД Ленинградский', 'seo_keywords': 'купить бетон, продажа нерудных материалов, бетонный завод ТД Ленинградский', 'city_slug': 'donetsk', 'city_name': 'Донецк', 'breadcrumbs': [{'title': 'Главная', 'url': '/'}, {'title': 'Каталог Донецк', 'url': '/catalog/donetsk/'}]}, {'block': <Block Node: content. Contents: [<TextNode: '\n    <div class="goods__s'>, <IncludeNode: template=<FilterExpression "'good/includes/breadcrumbs.html'">>, <TextNode: '\n    <!-- Конец хлебных к'>, <IncludeNode: template=<FilterExpression '"good/includes/mobile_menu.html"'>>, <TextNode: '\n        <h1>'>, <Variable Node: title>, <TextNode: '</h1>\n        '>, <IfNode>, <TextNode: '\n\n        <div class="pro'>, <IfNode>, <TextNode: '\n        </div>\n\n\n       '>, <IfNode>, <TextNode: '\n\n    </div>\n    </div>\n'>]>}, {}]
DEBUG 2025-03-18 21:08:41,612 base Exception while resolving variable 'short_description' in template 'good/products.html'.
Traceback (most recent call last):
  File "/home/igor/venv/lib/python3.10/site-packages/django/template/base.py", line 880, in _resolve_lookup
    current = current[bit]
  File "/home/igor/venv/lib/python3.10/site-packages/django/template/context.py", line 83, in __getitem__
    raise KeyError(key)
KeyError: 'short_description'

During handling of the above exception, another exception occurred:

Traceback (most recent call last):
  File "/home/igor/venv/lib/python3.10/site-packages/django/template/base.py", line 886, in _resolve_lookup
    if isinstance(current, BaseContext) and getattr(
AttributeError: type object 'RequestContext' has no attribute 'short_description'

During handling of the above exception, another exception occurred:

Traceback (most recent call last):
  File "/home/igor/venv/lib/python3.10/site-packages/django/template/base.py", line 896, in _resolve_lookup
    current = current[int(bit)]
ValueError: invalid literal for int() with base 10: 'short_description'

During handling of the above exception, another exception occurred:

Traceback (most recent call last):
  File "/home/igor/venv/lib/python3.10/site-packages/django/template/base.py", line 903, in _resolve_lookup
    raise VariableDoesNotExist(
django.template.base.VariableDoesNotExist: Failed lookup for key [short_description] in [{'True': True, 'False': False, 'None': None}, {'csrf_token': <SimpleLazyObject: '2p0U1hw43GNt8xc7qoD6WF6OdOyGxeK4rSiaseo9GNLKfA44B105VVMa4atxqo9X'>, 'request': <WSGIRequest: GET '/catalog/donetsk/'>, 'user': <SimpleLazyObject: <function AuthenticationMiddleware.process_request.<locals>.<lambda> at 0x7f94d902f5b0>>, 'perms': PermWrapper(<SimpleLazyObject: <function AuthenticationMiddleware.process_request.<locals>.<lambda> at 0x7f94d902f5b0>>), 'messages': <FallbackStorage: request=<WSGIRequest: GET '/catalog/donetsk/'>>, 'DEFAULT_MESSAGE_LEVELS': {'DEBUG': 10, 'INFO': 20, 'SUCCESS': 25, 'WARNING': 30, 'ERROR': 40}, 'STATIC_URL': '/static/', 'menu': [{'title': 'О компании', 'url_name': 'about'}, {'title': 'Контакты', 'url_name': 'contacts'}, {'title': 'Продукция', 'url_name': 'catalog'}, {'title': 'Услуги', 'url_name': 'services', 'children': [{'title': 'Калькулятор доставки', 'url_name': 'delivery'}, {'title': 'Калькулятор бетона', 'url_name': 'concrete_calculator'}]}, {'title': 'Блог', 'url_name': 'blog'}], 'city_slug': 'mariupol', 'city_name': 'Мариуполь', 'cities': <QuerySet [<City: Донецк>, <City: Мариуполь>, <City: Луганск>]>, 'city_slugs': ['donetsk', 'mariupol', 'lugansk']}, {}, {'title': 'Товарный каталог продукции ТД Ленинградский в ДНР: город Донецк', 'products': <QuerySet [<Product: Бетон М400>, <Product: Бетон М300>, <Product: Бетон М250>, <Product: Бетон М200>, <Product: Бетон М100>, <Product: Бетон М50>, <Product: Строительный песок>, <Product: Гранитный щебень 20-40>, <Product: Гранитный щебень 10-20>, <Product: Гранитный щебень 5-10>]>, 'seo_title': 'Товарный каталог продукции ТД Ленинградский в городе Донецк', 'seo_description': 'Бетон и нерудные материалы в ДНР, город Донецк от производителя | ТД Ленинградский', 'seo_keywords': 'купить бетон, продажа нерудных материалов, бетонный завод ТД Ленинградский', 'city_slug': 'donetsk', 'city_name': 'Донецк', 'breadcrumbs': [{'title': 'Главная', 'url': '/'}, {'title': 'Каталог Донецк', 'url': '/catalog/donetsk/'}]}, {'block': <Block Node: content. Contents: [<TextNode: '\n    <div class="goods__s'>, <IncludeNode: template=<FilterExpression "'good/includes/breadcrumbs.html'">>, <TextNode: '\n    <!-- Конец хлебных к'>, <IncludeNode: template=<FilterExpression '"good/includes/mobile_menu.html"'>>, <TextNode: '\n        <h1>'>, <Variable Node: title>, <TextNode: '</h1>\n        '>, <IfNode>, <TextNode: '\n\n        <div class="pro'>, <IfNode>, <TextNode: '\n        </div>\n\n\n       '>, <IfNode>, <TextNode: '\n\n    </div>\n    </div>\n'>]>}]
DEBUG 2025-03-18 21:08:41,642 base Exception while resolving variable 'description' in template 'good/products.html'.
Traceback (most recent call last):
  File "/home/igor/venv/lib/python3.10/site-packages/django/template/base.py", line 880, in _resolve_lookup
    current = current[bit]
  File "/home/igor/venv/lib/python3.10/site-packages/django/template/context.py", line 83, in __getitem__
    raise KeyError(key)
KeyError: 'description'

During handling of the above exception, another exception occurred:

Traceback (most recent call last):
  File "/home/igor/venv/lib/python3.10/site-packages/django/template/base.py", line 886, in _resolve_lookup
    if isinstance(current, BaseContext) and getattr(
AttributeError: type object 'RequestContext' has no attribute 'description'

During handling of the above exception, another exception occurred:

Traceback (most recent call last):
  File "/home/igor/venv/lib/python3.10/site-packages/django/template/base.py", line 896, in _resolve_lookup
    current = current[int(bit)]
ValueError: invalid literal for int() with base 10: 'description'

During handling of the above exception, another exception occurred:

Traceback (most recent call last):
  File "/home/igor/venv/lib/python3.10/site-packages/django/template/base.py", line 903, in _resolve_lookup
    raise VariableDoesNotExist(
django.template.base.VariableDoesNotExist: Failed lookup for key [description] in [{'True': True, 'False': False, 'None': None}, {'csrf_token': <SimpleLazyObject: '2p0U1hw43GNt8xc7qoD6WF6OdOyGxeK4rSiaseo9GNLKfA44B105VVMa4atxqo9X'>, 'request': <WSGIRequest: GET '/catalog/donetsk/'>, 'user': <SimpleLazyObject: <function AuthenticationMiddleware.process_request.<locals>.<lambda> at 0x7f94d902f5b0>>, 'perms': PermWrapper(<SimpleLazyObject: <function AuthenticationMiddleware.process_request.<locals>.<lambda> at 0x7f94d902f5b0>>), 'messages': <FallbackStorage: request=<WSGIRequest: GET '/catalog/donetsk/'>>, 'DEFAULT_MESSAGE_LEVELS': {'DEBUG': 10, 'INFO': 20, 'SUCCESS': 25, 'WARNING': 30, 'ERROR': 40}, 'STATIC_URL': '/static/', 'menu': [{'title': 'О компании', 'url_name': 'about'}, {'title': 'Контакты', 'url_name': 'contacts'}, {'title': 'Продукция', 'url_name': 'catalog'}, {'title': 'Услуги', 'url_name': 'services', 'children': [{'title': 'Калькулятор доставки', 'url_name': 'delivery'}, {'title': 'Калькулятор бетона', 'url_name': 'concrete_calculator'}]}, {'title': 'Блог', 'url_name': 'blog'}], 'city_slug': 'mariupol', 'city_name': 'Мариуполь', 'cities': <QuerySet [<City: Донецк>, <City: Мариуполь>, <City: Луганск>]>, 'city_slugs': ['donetsk', 'mariupol', 'lugansk']}, {}, {'title': 'Товарный каталог продукции ТД Ленинградский в ДНР: город Донецк', 'products': <QuerySet [<Product: Бетон М400>, <Product: Бетон М300>, <Product: Бетон М250>, <Product: Бетон М200>, <Product: Бетон М100>, <Product: Бетон М50>, <Product: Строительный песок>, <Product: Гранитный щебень 20-40>, <Product: Гранитный щебень 10-20>, <Product: Гранитный щебень 5-10>]>, 'seo_title': 'Товарный каталог продукции ТД Ленинградский в городе Донецк', 'seo_description': 'Бетон и нерудные материалы в ДНР, город Донецк от производителя | ТД Ленинградский', 'seo_keywords': 'купить бетон, продажа нерудных материалов, бетонный завод ТД Ленинградский', 'city_slug': 'donetsk', 'city_name': 'Донецк', 'breadcrumbs': [{'title': 'Главная', 'url': '/'}, {'title': 'Каталог Донецк', 'url': '/catalog/donetsk/'}]}, {'block': <Block Node: content. Contents: [<TextNode: '\n    <div class="goods__s'>, <IncludeNode: template=<FilterExpression "'good/includes/breadcrumbs.html'">>, <TextNode: '\n    <!-- Конец хлебных к'>, <IncludeNode: template=<FilterExpression '"good/includes/mobile_menu.html"'>>, <TextNode: '\n        <h1>'>, <Variable Node: title>, <TextNode: '</h1>\n        '>, <IfNode>, <TextNode: '\n\n        <div class="pro'>, <IfNode>, <TextNode: '\n        </div>\n\n\n       '>, <IfNode>, <TextNode: '\n\n    </div>\n    </div>\n'>]>}]
DEBUG 2025-03-18 21:08:41,645 base Exception while resolving variable 'show_city_modal' in template 'good/products.html'.
Traceback (most recent call last):
  File "/home/igor/venv/lib/python3.10/site-packages/django/template/base.py", line 880, in _resolve_lookup
    current = current[bit]
  File "/home/igor/venv/lib/python3.10/site-packages/django/template/context.py", line 83, in __getitem__
    raise KeyError(key)
KeyError: 'show_city_modal'

During handling of the above exception, another exception occurred:

Traceback (most recent call last):
  File "/home/igor/venv/lib/python3.10/site-packages/django/template/base.py", line 886, in _resolve_lookup
    if isinstance(current, BaseContext) and getattr(
AttributeError: type object 'RequestContext' has no attribute 'show_city_modal'

During handling of the above exception, another exception occurred:

Traceback (most recent call last):
  File "/home/igor/venv/lib/python3.10/site-packages/django/template/base.py", line 896, in _resolve_lookup
    current = current[int(bit)]
ValueError: invalid literal for int() with base 10: 'show_city_modal'

During handling of the above exception, another exception occurred:

Traceback (most recent call last):
  File "/home/igor/venv/lib/python3.10/site-packages/django/template/base.py", line 903, in _resolve_lookup
    raise VariableDoesNotExist(
django.template.base.VariableDoesNotExist: Failed lookup for key [show_city_modal] in [{'True': True, 'False': False, 'None': None}, {'csrf_token': <SimpleLazyObject: '2p0U1hw43GNt8xc7qoD6WF6OdOyGxeK4rSiaseo9GNLKfA44B105VVMa4atxqo9X'>, 'request': <WSGIRequest: GET '/catalog/donetsk/'>, 'user': <SimpleLazyObject: <function AuthenticationMiddleware.process_request.<locals>.<lambda> at 0x7f94d902f5b0>>, 'perms': PermWrapper(<SimpleLazyObject: <function AuthenticationMiddleware.process_request.<locals>.<lambda> at 0x7f94d902f5b0>>), 'messages': <FallbackStorage: request=<WSGIRequest: GET '/catalog/donetsk/'>>, 'DEFAULT_MESSAGE_LEVELS': {'DEBUG': 10, 'INFO': 20, 'SUCCESS': 25, 'WARNING': 30, 'ERROR': 40}, 'STATIC_URL': '/static/', 'menu': [{'title': 'О компании', 'url_name': 'about'}, {'title': 'Контакты', 'url_name': 'contacts'}, {'title': 'Продукция', 'url_name': 'catalog'}, {'title': 'Услуги', 'url_name': 'services', 'children': [{'title': 'Калькулятор доставки', 'url_name': 'delivery'}, {'title': 'Калькулятор бетона', 'url_name': 'concrete_calculator'}]}, {'title': 'Блог', 'url_name': 'blog'}], 'city_slug': 'mariupol', 'city_name': 'Мариуполь', 'cities': <QuerySet [<City: Донецк>, <City: Мариуполь>, <City: Луганск>]>, 'city_slugs': ['donetsk', 'mariupol', 'lugansk']}, {}, {'title': 'Товарный каталог продукции ТД Ленинградский в ДНР: город Донецк', 'products': <QuerySet [<Product: Бетон М400>, <Product: Бетон М300>, <Product: Бетон М250>, <Product: Бетон М200>, <Product: Бетон М100>, <Product: Бетон М50>, <Product: Строительный песок>, <Product: Гранитный щебень 20-40>, <Product: Гранитный щебень 10-20>, <Product: Гранитный щебень 5-10>]>, 'seo_title': 'Товарный каталог продукции ТД Ленинградский в городе Донецк', 'seo_description': 'Бетон и нерудные материалы в ДНР, город Донецк от производителя | ТД Ленинградский', 'seo_keywords': 'купить бетон, продажа нерудных материалов, бетонный завод ТД Ленинградский', 'city_slug': 'donetsk', 'city_name': 'Донецк', 'breadcrumbs': [{'title': 'Главная', 'url': '/'}, {'title': 'Каталог Донецк', 'url': '/catalog/donetsk/'}]}, {'block': <Block Node: extra_scripts. Contents: [<TextNode: '\n    '>, <IfNode>, <TextNode: '\n'>]>}]
DEBUG 2025-03-18 21:08:43,652 base Exception while resolving variable 'category_selected' in template 'good/products.html'.
Traceback (most recent call last):
  File "/home/igor/venv/lib/python3.10/site-packages/django/template/base.py", line 880, in _resolve_lookup
    current = current[bit]
  File "/home/igor/venv/lib/python3.10/site-packages/django/template/context.py", line 83, in __getitem__
    raise KeyError(key)
KeyError: 'category_selected'

During handling of the above exception, another exception occurred:

Traceback (most recent call last):
  File "/home/igor/venv/lib/python3.10/site-packages/django/template/base.py", line 886, in _resolve_lookup
    if isinstance(current, BaseContext) and getattr(
AttributeError: type object 'RequestContext' has no attribute 'category_selected'

During handling of the above exception, another exception occurred:

Traceback (most recent call last):
  File "/home/igor/venv/lib/python3.10/site-packages/django/template/base.py", line 896, in _resolve_lookup
    current = current[int(bit)]
ValueError: invalid literal for int() with base 10: 'category_selected'

During handling of the above exception, another exception occurred:

Traceback (most recent call last):
  File "/home/igor/venv/lib/python3.10/site-packages/django/template/base.py", line 903, in _resolve_lookup
    raise VariableDoesNotExist(
django.template.base.VariableDoesNotExist: Failed lookup for key [category_selected] in [{'True': True, 'False': False, 'None': None}, {'csrf_token': <SimpleLazyObject: 'NPxkWqoJSESF20N6WSp4cTyTvvmgEeevciPAnngOvLQW93F37vM3b9efmRh7xoDo'>, 'request': <WSGIRequest: GET '/catalog/mariupol/'>, 'user': <SimpleLazyObject: <function AuthenticationMiddleware.process_request.<locals>.<lambda> at 0x7f94d60e7a30>>, 'perms': PermWrapper(<SimpleLazyObject: <function AuthenticationMiddleware.process_request.<locals>.<lambda> at 0x7f94d60e7a30>>), 'messages': <FallbackStorage: request=<WSGIRequest: GET '/catalog/mariupol/'>>, 'DEFAULT_MESSAGE_LEVELS': {'DEBUG': 10, 'INFO': 20, 'SUCCESS': 25, 'WARNING': 30, 'ERROR': 40}, 'STATIC_URL': '/static/', 'menu': [{'title': 'О компании', 'url_name': 'about'}, {'title': 'Контакты', 'url_name': 'contacts'}, {'title': 'Продукция', 'url_name': 'catalog'}, {'title': 'Услуги', 'url_name': 'services', 'children': [{'title': 'Калькулятор доставки', 'url_name': 'delivery'}, {'title': 'Калькулятор бетона', 'url_name': 'concrete_calculator'}]}, {'title': 'Блог', 'url_name': 'blog'}], 'city_slug': 'mariupol', 'city_name': 'Мариуполь', 'cities': <QuerySet [<City: Донецк>, <City: Мариуполь>, <City: Луганск>]>, 'city_slugs': ['donetsk', 'mariupol', 'lugansk']}, {}, {'title': 'Товарный каталог продукции ТД Ленинградский в ДНР: город Мариуполь', 'products': <QuerySet [<Product: Асфальт тип Б марка 1 крупнозернистый плотный>, <Product: Гранитный щебень 20-40>, <Product: Гранитный щебень 10-20>, <Product: Гранитный щебень 5-10>, <Product: Бетон М400>, <Product: Бетон М300>, <Product: Бетон М250>, <Product: Бетон М200>, <Product: Бетон М50>, <Product: Бетон М100>]>, 'seo_title': 'Товарный каталог продукции ТД Ленинградский в городе Мариуполь', 'seo_description': 'Бетон и нерудные материалы в ДНР, город Мариуполь от производителя | ТД Ленинградский', 'seo_keywords': 'купить бетон, продажа нерудных материалов, бетонный завод ТД Ленинградский', 'city_slug': 'mariupol', 'city_name': 'Мариуполь', 'breadcrumbs': [{'title': 'Главная', 'url': '/'}, {'title': 'Каталог Мариуполь', 'url': '/catalog/mariupol/'}]}, {'block': <Block Node: sidebar. Contents: [<TextNode: '\n    <div class="goods__s'>, <IncludeNode: template=<FilterExpression '"good/includes/sidebar.html"'>>, <TextNode: '\n'>]>}, {}]
DEBUG 2025-03-18 21:08:43,660 base Exception while resolving variable 'category_selected' in template 'good/products.html'.
Traceback (most recent call last):
  File "/home/igor/venv/lib/python3.10/site-packages/django/template/base.py", line 880, in _resolve_lookup
    current = current[bit]
  File "/home/igor/venv/lib/python3.10/site-packages/django/template/context.py", line 83, in __getitem__
    raise KeyError(key)
KeyError: 'category_selected'

During handling of the above exception, another exception occurred:

Traceback (most recent call last):
  File "/home/igor/venv/lib/python3.10/site-packages/django/template/base.py", line 886, in _resolve_lookup
    if isinstance(current, BaseContext) and getattr(
AttributeError: type object 'RequestContext' has no attribute 'category_selected'

During handling of the above exception, another exception occurred:

Traceback (most recent call last):
  File "/home/igor/venv/lib/python3.10/site-packages/django/template/base.py", line 896, in _resolve_lookup
    current = current[int(bit)]
ValueError: invalid literal for int() with base 10: 'category_selected'

During handling of the above exception, another exception occurred:

Traceback (most recent call last):
  File "/home/igor/venv/lib/python3.10/site-packages/django/template/base.py", line 903, in _resolve_lookup
    raise VariableDoesNotExist(
django.template.base.VariableDoesNotExist: Failed lookup for key [category_selected] in [{'True': True, 'False': False, 'None': None}, {'csrf_token': <SimpleLazyObject: 'NPxkWqoJSESF20N6WSp4cTyTvvmgEeevciPAnngOvLQW93F37vM3b9efmRh7xoDo'>, 'request': <WSGIRequest: GET '/catalog/mariupol/'>, 'user': <SimpleLazyObject: <function AuthenticationMiddleware.process_request.<locals>.<lambda> at 0x7f94d60e7a30>>, 'perms': PermWrapper(<SimpleLazyObject: <function AuthenticationMiddleware.process_request.<locals>.<lambda> at 0x7f94d60e7a30>>), 'messages': <FallbackStorage: request=<WSGIRequest: GET '/catalog/mariupol/'>>, 'DEFAULT_MESSAGE_LEVELS': {'DEBUG': 10, 'INFO': 20, 'SUCCESS': 25, 'WARNING': 30, 'ERROR': 40}, 'STATIC_URL': '/static/', 'menu': [{'title': 'О компании', 'url_name': 'about'}, {'title': 'Контакты', 'url_name': 'contacts'}, {'title': 'Продукция', 'url_name': 'catalog'}, {'title': 'Услуги', 'url_name': 'services', 'children': [{'title': 'Калькулятор доставки', 'url_name': 'delivery'}, {'title': 'Калькулятор бетона', 'url_name': 'concrete_calculator'}]}, {'title': 'Блог', 'url_name': 'blog'}], 'city_slug': 'mariupol', 'city_name': 'Мариуполь', 'cities': <QuerySet [<City: Донецк>, <City: Мариуполь>, <City: Луганск>]>, 'city_slugs': ['donetsk', 'mariupol', 'lugansk']}, {}, {'title': 'Товарный каталог продукции ТД Ленинградский в ДНР: город Мариуполь', 'products': <QuerySet [<Product: Асфальт тип Б марка 1 крупнозернистый плотный>, <Product: Гранитный щебень 20-40>, <Product: Гранитный щебень 10-20>, <Product: Гранитный щебень 5-10>, <Product: Бетон М400>, <Product: Бетон М300>, <Product: Бетон М250>, <Product: Бетон М200>, <Product: Бетон М50>, <Product: Бетон М100>]>, 'seo_title': 'Товарный каталог продукции ТД Ленинградский в городе Мариуполь', 'seo_description': 'Бетон и нерудные материалы в ДНР, город Мариуполь от производителя | ТД Ленинградский', 'seo_keywords': 'купить бетон, продажа нерудных материалов, бетонный завод ТД Ленинградский', 'city_slug': 'mariupol', 'city_name': 'Мариуполь', 'breadcrumbs': [{'title': 'Главная', 'url': '/'}, {'title': 'Каталог Мариуполь', 'url': '/catalog/mariupol/'}]}, {'block': <Block Node: sidebar. Contents: [<TextNode: '\n    <div class="goods__s'>, <IncludeNode: template=<FilterExpression '"good/includes/sidebar.html"'>>, <TextNode: '\n'>]>}, {}]
DEBUG 2025-03-18 21:08:43,667 base Exception while resolving variable 'category_selected' in template 'good/products.html'.
Traceback (most recent call last):
  File "/home/igor/venv/lib/python3.10/site-packages/django/template/base.py", line 880, in _resolve_lookup
    current = current[bit]
  File "/home/igor/venv/lib/python3.10/site-packages/django/template/context.py", line 83, in __getitem__
    raise KeyError(key)
KeyError: 'category_selected'

During handling of the above exception, another exception occurred:

Traceback (most recent call last):
  File "/home/igor/venv/lib/python3.10/site-packages/django/template/base.py", line 886, in _resolve_lookup
    if isinstance(current, BaseContext) and getattr(
AttributeError: type object 'RequestContext' has no attribute 'category_selected'

During handling of the above exception, another exception occurred:

Traceback (most recent call last):
  File "/home/igor/venv/lib/python3.10/site-packages/django/template/base.py", line 896, in _resolve_lookup
    current = current[int(bit)]
ValueError: invalid literal for int() with base 10: 'category_selected'

During handling of the above exception, another exception occurred:

Traceback (most recent call last):
  File "/home/igor/venv/lib/python3.10/site-packages/django/template/base.py", line 903, in _resolve_lookup
    raise VariableDoesNotExist(
django.template.base.VariableDoesNotExist: Failed lookup for key [category_selected] in [{'True': True, 'False': False, 'None': None}, {'csrf_token': <SimpleLazyObject: 'NPxkWqoJSESF20N6WSp4cTyTvvmgEeevciPAnngOvLQW93F37vM3b9efmRh7xoDo'>, 'request': <WSGIRequest: GET '/catalog/mariupol/'>, 'user': <SimpleLazyObject: <function AuthenticationMiddleware.process_request.<locals>.<lambda> at 0x7f94d60e7a30>>, 'perms': PermWrapper(<SimpleLazyObject: <function AuthenticationMiddleware.process_request.<locals>.<lambda> at 0x7f94d60e7a30>>), 'messages': <FallbackStorage: request=<WSGIRequest: GET '/catalog/mariupol/'>>, 'DEFAULT_MESSAGE_LEVELS': {'DEBUG': 10, 'INFO': 20, 'SUCCESS': 25, 'WARNING': 30, 'ERROR': 40}, 'STATIC_URL': '/static/', 'menu': [{'title': 'О компании', 'url_name': 'about'}, {'title': 'Контакты', 'url_name': 'contacts'}, {'title': 'Продукция', 'url_name': 'catalog'}, {'title': 'Услуги', 'url_name': 'services', 'children': [{'title': 'Калькулятор доставки', 'url_name': 'delivery'}, {'title': 'Калькулятор бетона', 'url_name': 'concrete_calculator'}]}, {'title': 'Блог', 'url_name': 'blog'}], 'city_slug': 'mariupol', 'city_name': 'Мариуполь', 'cities': <QuerySet [<City: Донецк>, <City: Мариуполь>, <City: Луганск>]>, 'city_slugs': ['donetsk', 'mariupol', 'lugansk']}, {}, {'title': 'Товарный каталог продукции ТД Ленинградский в ДНР: город Мариуполь', 'products': <QuerySet [<Product: Асфальт тип Б марка 1 крупнозернистый плотный>, <Product: Гранитный щебень 20-40>, <Product: Гранитный щебень 10-20>, <Product: Гранитный щебень 5-10>, <Product: Бетон М400>, <Product: Бетон М300>, <Product: Бетон М250>, <Product: Бетон М200>, <Product: Бетон М50>, <Product: Бетон М100>]>, 'seo_title': 'Товарный каталог продукции ТД Ленинградский в городе Мариуполь', 'seo_description': 'Бетон и нерудные материалы в ДНР, город Мариуполь от производителя | ТД Ленинградский', 'seo_keywords': 'купить бетон, продажа нерудных материалов, бетонный завод ТД Ленинградский', 'city_slug': 'mariupol', 'city_name': 'Мариуполь', 'breadcrumbs': [{'title': 'Главная', 'url': '/'}, {'title': 'Каталог Мариуполь', 'url': '/catalog/mariupol/'}]}, {'block': <Block Node: sidebar. Contents: [<TextNode: '\n    <div class="goods__s'>, <IncludeNode: template=<FilterExpression '"good/includes/sidebar.html"'>>, <TextNode: '\n'>]>}, {}]
DEBUG 2025-03-18 21:08:43,679 base Exception while resolving variable 'category_selected' in template 'good/products.html'.
Traceback (most recent call last):
  File "/home/igor/venv/lib/python3.10/site-packages/django/template/base.py", line 880, in _resolve_lookup
    current = current[bit]
  File "/home/igor/venv/lib/python3.10/site-packages/django/template/context.py", line 83, in __getitem__
    raise KeyError(key)
KeyError: 'category_selected'

During handling of the above exception, another exception occurred:

Traceback (most recent call last):
  File "/home/igor/venv/lib/python3.10/site-packages/django/template/base.py", line 886, in _resolve_lookup
    if isinstance(current, BaseContext) and getattr(
AttributeError: type object 'RequestContext' has no attribute 'category_selected'

During handling of the above exception, another exception occurred:

Traceback (most recent call last):
  File "/home/igor/venv/lib/python3.10/site-packages/django/template/base.py", line 896, in _resolve_lookup
    current = current[int(bit)]
ValueError: invalid literal for int() with base 10: 'category_selected'

During handling of the above exception, another exception occurred:

Traceback (most recent call last):
  File "/home/igor/venv/lib/python3.10/site-packages/django/template/base.py", line 903, in _resolve_lookup
    raise VariableDoesNotExist(
django.template.base.VariableDoesNotExist: Failed lookup for key [category_selected] in [{'True': True, 'False': False, 'None': None}, {'csrf_token': <SimpleLazyObject: 'NPxkWqoJSESF20N6WSp4cTyTvvmgEeevciPAnngOvLQW93F37vM3b9efmRh7xoDo'>, 'request': <WSGIRequest: GET '/catalog/mariupol/'>, 'user': <SimpleLazyObject: <function AuthenticationMiddleware.process_request.<locals>.<lambda> at 0x7f94d60e7a30>>, 'perms': PermWrapper(<SimpleLazyObject: <function AuthenticationMiddleware.process_request.<locals>.<lambda> at 0x7f94d60e7a30>>), 'messages': <FallbackStorage: request=<WSGIRequest: GET '/catalog/mariupol/'>>, 'DEFAULT_MESSAGE_LEVELS': {'DEBUG': 10, 'INFO': 20, 'SUCCESS': 25, 'WARNING': 30, 'ERROR': 40}, 'STATIC_URL': '/static/', 'menu': [{'title': 'О компании', 'url_name': 'about'}, {'title': 'Контакты', 'url_name': 'contacts'}, {'title': 'Продукция', 'url_name': 'catalog'}, {'title': 'Услуги', 'url_name': 'services', 'children': [{'title': 'Калькулятор доставки', 'url_name': 'delivery'}, {'title': 'Калькулятор бетона', 'url_name': 'concrete_calculator'}]}, {'title': 'Блог', 'url_name': 'blog'}], 'city_slug': 'mariupol', 'city_name': 'Мариуполь', 'cities': <QuerySet [<City: Донецк>, <City: Мариуполь>, <City: Луганск>]>, 'city_slugs': ['donetsk', 'mariupol', 'lugansk']}, {}, {'title': 'Товарный каталог продукции ТД Ленинградский в ДНР: город Мариуполь', 'products': <QuerySet [<Product: Асфальт тип Б марка 1 крупнозернистый плотный>, <Product: Гранитный щебень 20-40>, <Product: Гранитный щебень 10-20>, <Product: Гранитный щебень 5-10>, <Product: Бетон М400>, <Product: Бетон М300>, <Product: Бетон М250>, <Product: Бетон М200>, <Product: Бетон М50>, <Product: Бетон М100>]>, 'seo_title': 'Товарный каталог продукции ТД Ленинградский в городе Мариуполь', 'seo_description': 'Бетон и нерудные материалы в ДНР, город Мариуполь от производителя | ТД Ленинградский', 'seo_keywords': 'купить бетон, продажа нерудных материалов, бетонный завод ТД Ленинградский', 'city_slug': 'mariupol', 'city_name': 'Мариуполь', 'breadcrumbs': [{'title': 'Главная', 'url': '/'}, {'title': 'Каталог Мариуполь', 'url': '/catalog/mariupol/'}]}, {'block': <Block Node: content. Contents: [<TextNode: '\n    <div class="goods__s'>, <IncludeNode: template=<FilterExpression "'good/includes/breadcrumbs.html'">>, <TextNode: '\n    <!-- Конец хлебных к'>, <IncludeNode: template=<FilterExpression '"good/includes/mobile_menu.html"'>>, <TextNode: '\n        <h1>'>, <Variable Node: title>, <TextNode: '</h1>\n        '>, <IfNode>, <TextNode: '\n\n        <div class="pro'>, <IfNode>, <TextNode: '\n        </div>\n\n\n       '>, <IfNode>, <TextNode: '\n\n    </div>\n    </div>\n'>]>}, {}]
DEBUG 2025-03-18 21:08:43,685 base Exception while resolving variable 'category_selected' in template 'good/products.html'.
Traceback (most recent call last):
  File "/home/igor/venv/lib/python3.10/site-packages/django/template/base.py", line 880, in _resolve_lookup
    current = current[bit]
  File "/home/igor/venv/lib/python3.10/site-packages/django/template/context.py", line 83, in __getitem__
    raise KeyError(key)
KeyError: 'category_selected'

During handling of the above exception, another exception occurred:

Traceback (most recent call last):
  File "/home/igor/venv/lib/python3.10/site-packages/django/template/base.py", line 886, in _resolve_lookup
    if isinstance(current, BaseContext) and getattr(
AttributeError: type object 'RequestContext' has no attribute 'category_selected'

During handling of the above exception, another exception occurred:

Traceback (most recent call last):
  File "/home/igor/venv/lib/python3.10/site-packages/django/template/base.py", line 896, in _resolve_lookup
    current = current[int(bit)]
ValueError: invalid literal for int() with base 10: 'category_selected'

During handling of the above exception, another exception occurred:

Traceback (most recent call last):
  File "/home/igor/venv/lib/python3.10/site-packages/django/template/base.py", line 903, in _resolve_lookup
    raise VariableDoesNotExist(
django.template.base.VariableDoesNotExist: Failed lookup for key [category_selected] in [{'True': True, 'False': False, 'None': None}, {'csrf_token': <SimpleLazyObject: 'NPxkWqoJSESF20N6WSp4cTyTvvmgEeevciPAnngOvLQW93F37vM3b9efmRh7xoDo'>, 'request': <WSGIRequest: GET '/catalog/mariupol/'>, 'user': <SimpleLazyObject: <function AuthenticationMiddleware.process_request.<locals>.<lambda> at 0x7f94d60e7a30>>, 'perms': PermWrapper(<SimpleLazyObject: <function AuthenticationMiddleware.process_request.<locals>.<lambda> at 0x7f94d60e7a30>>), 'messages': <FallbackStorage: request=<WSGIRequest: GET '/catalog/mariupol/'>>, 'DEFAULT_MESSAGE_LEVELS': {'DEBUG': 10, 'INFO': 20, 'SUCCESS': 25, 'WARNING': 30, 'ERROR': 40}, 'STATIC_URL': '/static/', 'menu': [{'title': 'О компании', 'url_name': 'about'}, {'title': 'Контакты', 'url_name': 'contacts'}, {'title': 'Продукция', 'url_name': 'catalog'}, {'title': 'Услуги', 'url_name': 'services', 'children': [{'title': 'Калькулятор доставки', 'url_name': 'delivery'}, {'title': 'Калькулятор бетона', 'url_name': 'concrete_calculator'}]}, {'title': 'Блог', 'url_name': 'blog'}], 'city_slug': 'mariupol', 'city_name': 'Мариуполь', 'cities': <QuerySet [<City: Донецк>, <City: Мариуполь>, <City: Луганск>]>, 'city_slugs': ['donetsk', 'mariupol', 'lugansk']}, {}, {'title': 'Товарный каталог продукции ТД Ленинградский в ДНР: город Мариуполь', 'products': <QuerySet [<Product: Асфальт тип Б марка 1 крупнозернистый плотный>, <Product: Гранитный щебень 20-40>, <Product: Гранитный щебень 10-20>, <Product: Гранитный щебень 5-10>, <Product: Бетон М400>, <Product: Бетон М300>, <Product: Бетон М250>, <Product: Бетон М200>, <Product: Бетон М50>, <Product: Бетон М100>]>, 'seo_title': 'Товарный каталог продукции ТД Ленинградский в городе Мариуполь', 'seo_description': 'Бетон и нерудные материалы в ДНР, город Мариуполь от производителя | ТД Ленинградский', 'seo_keywords': 'купить бетон, продажа нерудных материалов, бетонный завод ТД Ленинградский', 'city_slug': 'mariupol', 'city_name': 'Мариуполь', 'breadcrumbs': [{'title': 'Главная', 'url': '/'}, {'title': 'Каталог Мариуполь', 'url': '/catalog/mariupol/'}]}, {'block': <Block Node: content. Contents: [<TextNode: '\n    <div class="goods__s'>, <IncludeNode: template=<FilterExpression "'good/includes/breadcrumbs.html'">>, <TextNode: '\n    <!-- Конец хлебных к'>, <IncludeNode: template=<FilterExpression '"good/includes/mobile_menu.html"'>>, <TextNode: '\n        <h1>'>, <Variable Node: title>, <TextNode: '</h1>\n        '>, <IfNode>, <TextNode: '\n\n        <div class="pro'>, <IfNode>, <TextNode: '\n        </div>\n\n\n       '>, <IfNode>, <TextNode: '\n\n    </div>\n    </div>\n'>]>}, {}]
DEBUG 2025-03-18 21:08:43,692 base Exception while resolving variable 'category_selected' in template 'good/products.html'.
Traceback (most recent call last):
  File "/home/igor/venv/lib/python3.10/site-packages/django/template/base.py", line 880, in _resolve_lookup
    current = current[bit]
  File "/home/igor/venv/lib/python3.10/site-packages/django/template/context.py", line 83, in __getitem__
    raise KeyError(key)
KeyError: 'category_selected'

During handling of the above exception, another exception occurred:

Traceback (most recent call last):
  File "/home/igor/venv/lib/python3.10/site-packages/django/template/base.py", line 886, in _resolve_lookup
    if isinstance(current, BaseContext) and getattr(
AttributeError: type object 'RequestContext' has no attribute 'category_selected'

During handling of the above exception, another exception occurred:

Traceback (most recent call last):
  File "/home/igor/venv/lib/python3.10/site-packages/django/template/base.py", line 896, in _resolve_lookup
    current = current[int(bit)]
ValueError: invalid literal for int() with base 10: 'category_selected'

During handling of the above exception, another exception occurred:

Traceback (most recent call last):
  File "/home/igor/venv/lib/python3.10/site-packages/django/template/base.py", line 903, in _resolve_lookup
    raise VariableDoesNotExist(
django.template.base.VariableDoesNotExist: Failed lookup for key [category_selected] in [{'True': True, 'False': False, 'None': None}, {'csrf_token': <SimpleLazyObject: 'NPxkWqoJSESF20N6WSp4cTyTvvmgEeevciPAnngOvLQW93F37vM3b9efmRh7xoDo'>, 'request': <WSGIRequest: GET '/catalog/mariupol/'>, 'user': <SimpleLazyObject: <function AuthenticationMiddleware.process_request.<locals>.<lambda> at 0x7f94d60e7a30>>, 'perms': PermWrapper(<SimpleLazyObject: <function AuthenticationMiddleware.process_request.<locals>.<lambda> at 0x7f94d60e7a30>>), 'messages': <FallbackStorage: request=<WSGIRequest: GET '/catalog/mariupol/'>>, 'DEFAULT_MESSAGE_LEVELS': {'DEBUG': 10, 'INFO': 20, 'SUCCESS': 25, 'WARNING': 30, 'ERROR': 40}, 'STATIC_URL': '/static/', 'menu': [{'title': 'О компании', 'url_name': 'about'}, {'title': 'Контакты', 'url_name': 'contacts'}, {'title': 'Продукция', 'url_name': 'catalog'}, {'title': 'Услуги', 'url_name': 'services', 'children': [{'title': 'Калькулятор доставки', 'url_name': 'delivery'}, {'title': 'Калькулятор бетона', 'url_name': 'concrete_calculator'}]}, {'title': 'Блог', 'url_name': 'blog'}], 'city_slug': 'mariupol', 'city_name': 'Мариуполь', 'cities': <QuerySet [<City: Донецк>, <City: Мариуполь>, <City: Луганск>]>, 'city_slugs': ['donetsk', 'mariupol', 'lugansk']}, {}, {'title': 'Товарный каталог продукции ТД Ленинградский в ДНР: город Мариуполь', 'products': <QuerySet [<Product: Асфальт тип Б марка 1 крупнозернистый плотный>, <Product: Гранитный щебень 20-40>, <Product: Гранитный щебень 10-20>, <Product: Гранитный щебень 5-10>, <Product: Бетон М400>, <Product: Бетон М300>, <Product: Бетон М250>, <Product: Бетон М200>, <Product: Бетон М50>, <Product: Бетон М100>]>, 'seo_title': 'Товарный каталог продукции ТД Ленинградский в городе Мариуполь', 'seo_description': 'Бетон и нерудные материалы в ДНР, город Мариуполь от производителя | ТД Ленинградский', 'seo_keywords': 'купить бетон, продажа нерудных материалов, бетонный завод ТД Ленинградский', 'city_slug': 'mariupol', 'city_name': 'Мариуполь', 'breadcrumbs': [{'title': 'Главная', 'url': '/'}, {'title': 'Каталог Мариуполь', 'url': '/catalog/mariupol/'}]}, {'block': <Block Node: content. Contents: [<TextNode: '\n    <div class="goods__s'>, <IncludeNode: template=<FilterExpression "'good/includes/breadcrumbs.html'">>, <TextNode: '\n    <!-- Конец хлебных к'>, <IncludeNode: template=<FilterExpression '"good/includes/mobile_menu.html"'>>, <TextNode: '\n        <h1>'>, <Variable Node: title>, <TextNode: '</h1>\n        '>, <IfNode>, <TextNode: '\n\n        <div class="pro'>, <IfNode>, <TextNode: '\n        </div>\n\n\n       '>, <IfNode>, <TextNode: '\n\n    </div>\n    </div>\n'>]>}, {}]
DEBUG 2025-03-18 21:08:43,702 base Exception while resolving variable 'short_description' in template 'good/products.html'.
Traceback (most recent call last):
  File "/home/igor/venv/lib/python3.10/site-packages/django/template/base.py", line 880, in _resolve_lookup
    current = current[bit]
  File "/home/igor/venv/lib/python3.10/site-packages/django/template/context.py", line 83, in __getitem__
    raise KeyError(key)
KeyError: 'short_description'

During handling of the above exception, another exception occurred:

Traceback (most recent call last):
  File "/home/igor/venv/lib/python3.10/site-packages/django/template/base.py", line 886, in _resolve_lookup
    if isinstance(current, BaseContext) and getattr(
AttributeError: type object 'RequestContext' has no attribute 'short_description'

During handling of the above exception, another exception occurred:

Traceback (most recent call last):
  File "/home/igor/venv/lib/python3.10/site-packages/django/template/base.py", line 896, in _resolve_lookup
    current = current[int(bit)]
ValueError: invalid literal for int() with base 10: 'short_description'

During handling of the above exception, another exception occurred:

Traceback (most recent call last):
  File "/home/igor/venv/lib/python3.10/site-packages/django/template/base.py", line 903, in _resolve_lookup
    raise VariableDoesNotExist(
django.template.base.VariableDoesNotExist: Failed lookup for key [short_description] in [{'True': True, 'False': False, 'None': None}, {'csrf_token': <SimpleLazyObject: 'NPxkWqoJSESF20N6WSp4cTyTvvmgEeevciPAnngOvLQW93F37vM3b9efmRh7xoDo'>, 'request': <WSGIRequest: GET '/catalog/mariupol/'>, 'user': <SimpleLazyObject: <function AuthenticationMiddleware.process_request.<locals>.<lambda> at 0x7f94d60e7a30>>, 'perms': PermWrapper(<SimpleLazyObject: <function AuthenticationMiddleware.process_request.<locals>.<lambda> at 0x7f94d60e7a30>>), 'messages': <FallbackStorage: request=<WSGIRequest: GET '/catalog/mariupol/'>>, 'DEFAULT_MESSAGE_LEVELS': {'DEBUG': 10, 'INFO': 20, 'SUCCESS': 25, 'WARNING': 30, 'ERROR': 40}, 'STATIC_URL': '/static/', 'menu': [{'title': 'О компании', 'url_name': 'about'}, {'title': 'Контакты', 'url_name': 'contacts'}, {'title': 'Продукция', 'url_name': 'catalog'}, {'title': 'Услуги', 'url_name': 'services', 'children': [{'title': 'Калькулятор доставки', 'url_name': 'delivery'}, {'title': 'Калькулятор бетона', 'url_name': 'concrete_calculator'}]}, {'title': 'Блог', 'url_name': 'blog'}], 'city_slug': 'mariupol', 'city_name': 'Мариуполь', 'cities': <QuerySet [<City: Донецк>, <City: Мариуполь>, <City: Луганск>]>, 'city_slugs': ['donetsk', 'mariupol', 'lugansk']}, {}, {'title': 'Товарный каталог продукции ТД Ленинградский в ДНР: город Мариуполь', 'products': <QuerySet [<Product: Асфальт тип Б марка 1 крупнозернистый плотный>, <Product: Гранитный щебень 20-40>, <Product: Гранитный щебень 10-20>, <Product: Гранитный щебень 5-10>, <Product: Бетон М400>, <Product: Бетон М300>, <Product: Бетон М250>, <Product: Бетон М200>, <Product: Бетон М50>, <Product: Бетон М100>]>, 'seo_title': 'Товарный каталог продукции ТД Ленинградский в городе Мариуполь', 'seo_description': 'Бетон и нерудные материалы в ДНР, город Мариуполь от производителя | ТД Ленинградский', 'seo_keywords': 'купить бетон, продажа нерудных материалов, бетонный завод ТД Ленинградский', 'city_slug': 'mariupol', 'city_name': 'Мариуполь', 'breadcrumbs': [{'title': 'Главная', 'url': '/'}, {'title': 'Каталог Мариуполь', 'url': '/catalog/mariupol/'}]}, {'block': <Block Node: content. Contents: [<TextNode: '\n    <div class="goods__s'>, <IncludeNode: template=<FilterExpression "'good/includes/breadcrumbs.html'">>, <TextNode: '\n    <!-- Конец хлебных к'>, <IncludeNode: template=<FilterExpression '"good/includes/mobile_menu.html"'>>, <TextNode: '\n        <h1>'>, <Variable Node: title>, <TextNode: '</h1>\n        '>, <IfNode>, <TextNode: '\n\n        <div class="pro'>, <IfNode>, <TextNode: '\n        </div>\n\n\n       '>, <IfNode>, <TextNode: '\n\n    </div>\n    </div>\n'>]>}]
DEBUG 2025-03-18 21:08:43,727 base Exception while resolving variable 'description' in template 'good/products.html'.
Traceback (most recent call last):
  File "/home/igor/venv/lib/python3.10/site-packages/django/template/base.py", line 880, in _resolve_lookup
    current = current[bit]
  File "/home/igor/venv/lib/python3.10/site-packages/django/template/context.py", line 83, in __getitem__
    raise KeyError(key)
KeyError: 'description'

During handling of the above exception, another exception occurred:

Traceback (most recent call last):
  File "/home/igor/venv/lib/python3.10/site-packages/django/template/base.py", line 886, in _resolve_lookup
    if isinstance(current, BaseContext) and getattr(
AttributeError: type object 'RequestContext' has no attribute 'description'

During handling of the above exception, another exception occurred:

Traceback (most recent call last):
  File "/home/igor/venv/lib/python3.10/site-packages/django/template/base.py", line 896, in _resolve_lookup
    current = current[int(bit)]
ValueError: invalid literal for int() with base 10: 'description'

During handling of the above exception, another exception occurred:

Traceback (most recent call last):
  File "/home/igor/venv/lib/python3.10/site-packages/django/template/base.py", line 903, in _resolve_lookup
    raise VariableDoesNotExist(
django.template.base.VariableDoesNotExist: Failed lookup for key [description] in [{'True': True, 'False': False, 'None': None}, {'csrf_token': <SimpleLazyObject: 'NPxkWqoJSESF20N6WSp4cTyTvvmgEeevciPAnngOvLQW93F37vM3b9efmRh7xoDo'>, 'request': <WSGIRequest: GET '/catalog/mariupol/'>, 'user': <SimpleLazyObject: <function AuthenticationMiddleware.process_request.<locals>.<lambda> at 0x7f94d60e7a30>>, 'perms': PermWrapper(<SimpleLazyObject: <function AuthenticationMiddleware.process_request.<locals>.<lambda> at 0x7f94d60e7a30>>), 'messages': <FallbackStorage: request=<WSGIRequest: GET '/catalog/mariupol/'>>, 'DEFAULT_MESSAGE_LEVELS': {'DEBUG': 10, 'INFO': 20, 'SUCCESS': 25, 'WARNING': 30, 'ERROR': 40}, 'STATIC_URL': '/static/', 'menu': [{'title': 'О компании', 'url_name': 'about'}, {'title': 'Контакты', 'url_name': 'contacts'}, {'title': 'Продукция', 'url_name': 'catalog'}, {'title': 'Услуги', 'url_name': 'services', 'children': [{'title': 'Калькулятор доставки', 'url_name': 'delivery'}, {'title': 'Калькулятор бетона', 'url_name': 'concrete_calculator'}]}, {'title': 'Блог', 'url_name': 'blog'}], 'city_slug': 'mariupol', 'city_name': 'Мариуполь', 'cities': <QuerySet [<City: Донецк>, <City: Мариуполь>, <City: Луганск>]>, 'city_slugs': ['donetsk', 'mariupol', 'lugansk']}, {}, {'title': 'Товарный каталог продукции ТД Ленинградский в ДНР: город Мариуполь', 'products': <QuerySet [<Product: Асфальт тип Б марка 1 крупнозернистый плотный>, <Product: Гранитный щебень 20-40>, <Product: Гранитный щебень 10-20>, <Product: Гранитный щебень 5-10>, <Product: Бетон М400>, <Product: Бетон М300>, <Product: Бетон М250>, <Product: Бетон М200>, <Product: Бетон М50>, <Product: Бетон М100>]>, 'seo_title': 'Товарный каталог продукции ТД Ленинградский в городе Мариуполь', 'seo_description': 'Бетон и нерудные материалы в ДНР, город Мариуполь от производителя | ТД Ленинградский', 'seo_keywords': 'купить бетон, продажа нерудных материалов, бетонный завод ТД Ленинградский', 'city_slug': 'mariupol', 'city_name': 'Мариуполь', 'breadcrumbs': [{'title': 'Главная', 'url': '/'}, {'title': 'Каталог Мариуполь', 'url': '/catalog/mariupol/'}]}, {'block': <Block Node: content. Contents: [<TextNode: '\n    <div class="goods__s'>, <IncludeNode: template=<FilterExpression "'good/includes/breadcrumbs.html'">>, <TextNode: '\n    <!-- Конец хлебных к'>, <IncludeNode: template=<FilterExpression '"good/includes/mobile_menu.html"'>>, <TextNode: '\n        <h1>'>, <Variable Node: title>, <TextNode: '</h1>\n        '>, <IfNode>, <TextNode: '\n\n        <div class="pro'>, <IfNode>, <TextNode: '\n        </div>\n\n\n       '>, <IfNode>, <TextNode: '\n\n    </div>\n    </div>\n'>]>}]
DEBUG 2025-03-18 21:08:43,730 base Exception while resolving variable 'show_city_modal' in template 'good/products.html'.
Traceback (most recent call last):
  File "/home/igor/venv/lib/python3.10/site-packages/django/template/base.py", line 880, in _resolve_lookup
    current = current[bit]
  File "/home/igor/venv/lib/python3.10/site-packages/django/template/context.py", line 83, in __getitem__
    raise KeyError(key)
KeyError: 'show_city_modal'

During handling of the above exception, another exception occurred:

Traceback (most recent call last):
  File "/home/igor/venv/lib/python3.10/site-packages/django/template/base.py", line 886, in _resolve_lookup
    if isinstance(current, BaseContext) and getattr(
AttributeError: type object 'RequestContext' has no attribute 'show_city_modal'

During handling of the above exception, another exception occurred:

Traceback (most recent call last):
  File "/home/igor/venv/lib/python3.10/site-packages/django/template/base.py", line 896, in _resolve_lookup
    current = current[int(bit)]
ValueError: invalid literal for int() with base 10: 'show_city_modal'

During handling of the above exception, another exception occurred:

Traceback (most recent call last):
  File "/home/igor/venv/lib/python3.10/site-packages/django/template/base.py", line 903, in _resolve_lookup
    raise VariableDoesNotExist(
django.template.base.VariableDoesNotExist: Failed lookup for key [show_city_modal] in [{'True': True, 'False': False, 'None': None}, {'csrf_token': <SimpleLazyObject: 'NPxkWqoJSESF20N6WSp4cTyTvvmgEeevciPAnngOvLQW93F37vM3b9efmRh7xoDo'>, 'request': <WSGIRequest: GET '/catalog/mariupol/'>, 'user': <SimpleLazyObject: <function AuthenticationMiddleware.process_request.<locals>.<lambda> at 0x7f94d60e7a30>>, 'perms': PermWrapper(<SimpleLazyObject: <function AuthenticationMiddleware.process_request.<locals>.<lambda> at 0x7f94d60e7a30>>), 'messages': <FallbackStorage: request=<WSGIRequest: GET '/catalog/mariupol/'>>, 'DEFAULT_MESSAGE_LEVELS': {'DEBUG': 10, 'INFO': 20, 'SUCCESS': 25, 'WARNING': 30, 'ERROR': 40}, 'STATIC_URL': '/static/', 'menu': [{'title': 'О компании', 'url_name': 'about'}, {'title': 'Контакты', 'url_name': 'contacts'}, {'title': 'Продукция', 'url_name': 'catalog'}, {'title': 'Услуги', 'url_name': 'services', 'children': [{'title': 'Калькулятор доставки', 'url_name': 'delivery'}, {'title': 'Калькулятор бетона', 'url_name': 'concrete_calculator'}]}, {'title': 'Блог', 'url_name': 'blog'}], 'city_slug': 'mariupol', 'city_name': 'Мариуполь', 'cities': <QuerySet [<City: Донецк>, <City: Мариуполь>, <City: Луганск>]>, 'city_slugs': ['donetsk', 'mariupol', 'lugansk']}, {}, {'title': 'Товарный каталог продукции ТД Ленинградский в ДНР: город Мариуполь', 'products': <QuerySet [<Product: Асфальт тип Б марка 1 крупнозернистый плотный>, <Product: Гранитный щебень 20-40>, <Product: Гранитный щебень 10-20>, <Product: Гранитный щебень 5-10>, <Product: Бетон М400>, <Product: Бетон М300>, <Product: Бетон М250>, <Product: Бетон М200>, <Product: Бетон М50>, <Product: Бетон М100>]>, 'seo_title': 'Товарный каталог продукции ТД Ленинградский в городе Мариуполь', 'seo_description': 'Бетон и нерудные материалы в ДНР, город Мариуполь от производителя | ТД Ленинградский', 'seo_keywords': 'купить бетон, продажа нерудных материалов, бетонный завод ТД Ленинградский', 'city_slug': 'mariupol', 'city_name': 'Мариуполь', 'breadcrumbs': [{'title': 'Главная', 'url': '/'}, {'title': 'Каталог Мариуполь', 'url': '/catalog/mariupol/'}]}, {'block': <Block Node: extra_scripts. Contents: [<TextNode: '\n    '>, <IfNode>, <TextNode: '\n'>]>}]
WARNING 2025-03-18 21:19:50,416 log Not Found: /catalog/rostov/
DEBUG 2025-03-18 21:26:09,300 base Exception while resolving variable 'show_city_modal' in template 'good/products.html'.
Traceback (most recent call last):
  File "/home/igor/venv/lib/python3.10/site-packages/django/template/base.py", line 880, in _resolve_lookup
    current = current[bit]
  File "/home/igor/venv/lib/python3.10/site-packages/django/template/context.py", line 83, in __getitem__
    raise KeyError(key)
KeyError: 'show_city_modal'

During handling of the above exception, another exception occurred:

Traceback (most recent call last):
  File "/home/igor/venv/lib/python3.10/site-packages/django/template/base.py", line 886, in _resolve_lookup
    if isinstance(current, BaseContext) and getattr(
AttributeError: type object 'RequestContext' has no attribute 'show_city_modal'

During handling of the above exception, another exception occurred:

Traceback (most recent call last):
  File "/home/igor/venv/lib/python3.10/site-packages/django/template/base.py", line 896, in _resolve_lookup
    current = current[int(bit)]
ValueError: invalid literal for int() with base 10: 'show_city_modal'

During handling of the above exception, another exception occurred:

Traceback (most recent call last):
  File "/home/igor/venv/lib/python3.10/site-packages/django/template/base.py", line 903, in _resolve_lookup
    raise VariableDoesNotExist(
django.template.base.VariableDoesNotExist: Failed lookup for key [show_city_modal] in [{'True': True, 'False': False, 'None': None}, {'csrf_token': <SimpleLazyObject: 'a0ZzZEQS87ShDikWr4NkpQtrAKosT28vPsxyqbOC9sqTvvV7cjBh4g3FKLPNywl7'>, 'request': <WSGIRequest: GET '/catalog/lugansk/asfalt/'>, 'user': <SimpleLazyObject: <function AuthenticationMiddleware.process_request.<locals>.<lambda> at 0x7f94d902f640>>, 'perms': PermWrapper(<SimpleLazyObject: <function AuthenticationMiddleware.process_request.<locals>.<lambda> at 0x7f94d902f640>>), 'messages': <FallbackStorage: request=<WSGIRequest: GET '/catalog/lugansk/asfalt/'>>, 'DEFAULT_MESSAGE_LEVELS': {'DEBUG': 10, 'INFO': 20, 'SUCCESS': 25, 'WARNING': 30, 'ERROR': 40}, 'STATIC_URL': '/static/', 'menu': [{'title': 'О компании', 'url_name': 'about'}, {'title': 'Контакты', 'url_name': 'contacts'}, {'title': 'Продукция', 'url_name': 'catalog'}, {'title': 'Услуги', 'url_name': 'services', 'children': [{'title': 'Калькулятор доставки', 'url_name': 'delivery'}, {'title': 'Калькулятор бетона', 'url_name': 'concrete_calculator'}]}, {'title': 'Блог', 'url_name': 'blog'}], 'city_slug': 'mariupol', 'city_name': 'Мариуполь', 'cities': <QuerySet [<City: Донецк>, <City: Мариуполь>, <City: Луганск>]>, 'city_slugs': ['donetsk', 'mariupol', 'lugansk']}, {}, {'title': 'Купить Асфальт от производителя продукции ТД Ленинградский в городе Луганск', 'products': <QuerySet [<Product: Асфальт тип Б марка 1 крупнозернистый плотный>]>, 'category_selected': 6, 'description': 'Асфальт — это высококачественный материал, широко применяемый для дорожного строительства, ремонта площадок и укладки покрытия на промышленных и жилых объектах. Мы предлагаем несколько видов асфальтобетонных смесей, подходящих для разных задач: от укладки дорог и тротуаров до ремонта небольших участков. В нашем каталоге вы найдете как горячие, так и холодные асфальтобетонные смеси, подходящие для любых климатических условий и сезонных работ.\r\n\r\nАссортимент продукции:\r\n\r\n\t1.\tГорячие асфальтобетонные смеси — идеальны для создания долговечных дорожных покрытий. Включают крупнозернистый, мелкозернистый и щебёночно-мастичный асфальт, который обеспечивает прочность и устойчивость к нагрузкам.\r\n\t2.\tХолодный асфальт — удобен для ремонта дорог и укладки в условиях низких температур, не требует специального оборудования для укладки.\r\n\t3.\tЦветной асфальт — используется для декоративных целей и создания разметок на дорогах и парковых зонах.\r\n\r\nПреимущества работы с нами:\r\n\r\n\t•\tПрямые поставки с завода — отсутствие посредников позволяет нам поддерживать доступные цены.\r\n\t•\tШирокий выбор смесей — для разных типов дорожного покрытия и климатических условий.\r\n\t•\tДоставка до объекта — организуем быструю доставку к вашему объекту.\r\n\t•\tГибкость в объемах заказов — вы можете приобрести асфальт как для небольших участков, так и для крупных объектов.\r\n\r\nЗакажите асфальт прямо сейчас с возможностью доставки на ваш объект и получите консультацию от наших специалистов, которые помогут вам подобрать идеальную смесь под ваш проект.', 'short_description': 'Асфальтные смеси используются для укладки дорог и тротуаров, благоустройства территорий и промышленных объектов. Мы предлагаем качественный асфальт для ремонта и строительства дорог с доставкой на ваш объект. Асфальт производится по ГОСТ, что обеспечивает его долговечность и износостойкость', 'seo_title': 'Купить асфальт в городе Луганск', 'seo_description': 'Купить Асфальт в городе Луганск. Каталог продукции ТД Ленинградский: Асфальт тип Б марка 1 крупнозернистый плотный.', 'seo_keywords': '', 'city_slug': 'lugansk', 'city_name': 'Луганск', 'breadcrumbs': [{'title': 'Главная', 'url': '/'}, {'title': 'Каталог Луганск', 'url': '/catalog/lugansk/'}, {'title': 'Асфальт', 'url': '/catalog/lugansk/asfalt/'}]}, {'block': <Block Node: extra_scripts. Contents: [<TextNode: '\n    '>, <IfNode>, <TextNode: '\n'>]>}]
DEBUG 2025-03-18 21:26:19,081 base Exception while resolving variable 'image' in template 'sitemap_with_images.xml'.
Traceback (most recent call last):
  File "/home/igor/venv/lib/python3.10/site-packages/django/template/base.py", line 880, in _resolve_lookup
    current = current[bit]
KeyError: 'image'

During handling of the above exception, another exception occurred:

Traceback (most recent call last):
  File "/home/igor/venv/lib/python3.10/site-packages/django/template/base.py", line 890, in _resolve_lookup
    current = getattr(current, bit)
AttributeError: 'dict' object has no attribute 'image'

During handling of the above exception, another exception occurred:

Traceback (most recent call last):
  File "/home/igor/venv/lib/python3.10/site-packages/django/template/base.py", line 896, in _resolve_lookup
    current = current[int(bit)]
ValueError: invalid literal for int() with base 10: 'image'

During handling of the above exception, another exception occurred:

Traceback (most recent call last):
  File "/home/igor/venv/lib/python3.10/site-packages/django/template/base.py", line 903, in _resolve_lookup
    raise VariableDoesNotExist(
django.template.base.VariableDoesNotExist: Failed lookup for key [image] in {'item': 'home', 'location': 'https://tdleningrad.ru/', 'lastmod': datetime.datetime(2025, 3, 18, 21, 26, 18, 968626), 'changefreq': 'daily', 'priority': '0.8', 'alternates': []}
DEBUG 2025-03-18 21:26:19,082 base Exception while resolving variable 'image' in template 'sitemap_with_images.xml'.
Traceback (most recent call last):
  File "/home/igor/venv/lib/python3.10/site-packages/django/template/base.py", line 880, in _resolve_lookup
    current = current[bit]
KeyError: 'image'

During handling of the above exception, another exception occurred:

Traceback (most recent call last):
  File "/home/igor/venv/lib/python3.10/site-packages/django/template/base.py", line 890, in _resolve_lookup
    current = getattr(current, bit)
AttributeError: 'dict' object has no attribute 'image'

During handling of the above exception, another exception occurred:

Traceback (most recent call last):
  File "/home/igor/venv/lib/python3.10/site-packages/django/template/base.py", line 896, in _resolve_lookup
    current = current[int(bit)]
ValueError: invalid literal for int() with base 10: 'image'

During handling of the above exception, another exception occurred:

Traceback (most recent call last):
  File "/home/igor/venv/lib/python3.10/site-packages/django/template/base.py", line 903, in _resolve_lookup
    raise VariableDoesNotExist(
django.template.base.VariableDoesNotExist: Failed lookup for key [image] in {'item': 'about', 'location': 'https://tdleningrad.ru/about/', 'lastmod': datetime.datetime(2025, 3, 18, 21, 26, 18, 968693), 'changefreq': 'daily', 'priority': '0.8', 'alternates': []}
DEBUG 2025-03-18 21:26:19,082 base Exception while resolving variable 'image' in template 'sitemap_with_images.xml'.
Traceback (most recent call last):
  File "/home/igor/venv/lib/python3.10/site-packages/django/template/base.py", line 880, in _resolve_lookup
    current = current[bit]
KeyError: 'image'

During handling of the above exception, another exception occurred:

Traceback (most recent call last):
  File "/home/igor/venv/lib/python3.10/site-packages/django/template/base.py", line 890, in _resolve_lookup
    current = getattr(current, bit)
AttributeError: 'dict' object has no attribute 'image'

During handling of the above exception, another exception occurred:

Traceback (most recent call last):
  File "/home/igor/venv/lib/python3.10/site-packages/django/template/base.py", line 896, in _resolve_lookup
    current = current[int(bit)]
ValueError: invalid literal for int() with base 10: 'image'

During handling of the above exception, another exception occurred:

Traceback (most recent call last):
  File "/home/igor/venv/lib/python3.10/site-packages/django/template/base.py", line 903, in _resolve_lookup
    raise VariableDoesNotExist(
django.template.base.VariableDoesNotExist: Failed lookup for key [image] in {'item': 'contacts', 'location': 'https://tdleningrad.ru/contacts/', 'lastmod': datetime.datetime(2025, 3, 18, 21, 26, 18, 968747), 'changefreq': 'daily', 'priority': '0.8', 'alternates': []}
DEBUG 2025-03-18 21:26:19,083 base Exception while resolving variable 'image' in template 'sitemap_with_images.xml'.
Traceback (most recent call last):
  File "/home/igor/venv/lib/python3.10/site-packages/django/template/base.py", line 880, in _resolve_lookup
    current = current[bit]
KeyError: 'image'

During handling of the above exception, another exception occurred:

Traceback (most recent call last):
  File "/home/igor/venv/lib/python3.10/site-packages/django/template/base.py", line 890, in _resolve_lookup
    current = getattr(current, bit)
AttributeError: 'dict' object has no attribute 'image'

During handling of the above exception, another exception occurred:

Traceback (most recent call last):
  File "/home/igor/venv/lib/python3.10/site-packages/django/template/base.py", line 896, in _resolve_lookup
    current = current[int(bit)]
ValueError: invalid literal for int() with base 10: 'image'

During handling of the above exception, another exception occurred:

Traceback (most recent call last):
  File "/home/igor/venv/lib/python3.10/site-packages/django/template/base.py", line 903, in _resolve_lookup
    raise VariableDoesNotExist(
django.template.base.VariableDoesNotExist: Failed lookup for key [image] in {'item': 'services', 'location': 'https://tdleningrad.ru/services/', 'lastmod': datetime.datetime(2025, 3, 18, 21, 26, 18, 969374), 'changefreq': 'daily', 'priority': '0.8', 'alternates': []}
DEBUG 2025-03-18 21:26:19,084 base Exception while resolving variable 'image' in template 'sitemap_with_images.xml'.
Traceback (most recent call last):
  File "/home/igor/venv/lib/python3.10/site-packages/django/template/base.py", line 880, in _resolve_lookup
    current = current[bit]
KeyError: 'image'

During handling of the above exception, another exception occurred:

Traceback (most recent call last):
  File "/home/igor/venv/lib/python3.10/site-packages/django/template/base.py", line 890, in _resolve_lookup
    current = getattr(current, bit)
AttributeError: 'dict' object has no attribute 'image'

During handling of the above exception, another exception occurred:

Traceback (most recent call last):
  File "/home/igor/venv/lib/python3.10/site-packages/django/template/base.py", line 896, in _resolve_lookup
    current = current[int(bit)]
ValueError: invalid literal for int() with base 10: 'image'

During handling of the above exception, another exception occurred:

Traceback (most recent call last):
  File "/home/igor/venv/lib/python3.10/site-packages/django/template/base.py", line 903, in _resolve_lookup
    raise VariableDoesNotExist(
django.template.base.VariableDoesNotExist: Failed lookup for key [image] in {'item': 'delivery', 'location': 'https://tdleningrad.ru/services/delivery/', 'lastmod': datetime.datetime(2025, 3, 18, 21, 26, 18, 969448), 'changefreq': 'daily', 'priority': '0.8', 'alternates': []}
DEBUG 2025-03-18 21:26:19,084 base Exception while resolving variable 'image' in template 'sitemap_with_images.xml'.
Traceback (most recent call last):
  File "/home/igor/venv/lib/python3.10/site-packages/django/template/base.py", line 880, in _resolve_lookup
    current = current[bit]
KeyError: 'image'

During handling of the above exception, another exception occurred:

Traceback (most recent call last):
  File "/home/igor/venv/lib/python3.10/site-packages/django/template/base.py", line 890, in _resolve_lookup
    current = getattr(current, bit)
AttributeError: 'dict' object has no attribute 'image'

During handling of the above exception, another exception occurred:

Traceback (most recent call last):
  File "/home/igor/venv/lib/python3.10/site-packages/django/template/base.py", line 896, in _resolve_lookup
    current = current[int(bit)]
ValueError: invalid literal for int() with base 10: 'image'

During handling of the above exception, another exception occurred:

Traceback (most recent call last):
  File "/home/igor/venv/lib/python3.10/site-packages/django/template/base.py", line 903, in _resolve_lookup
    raise VariableDoesNotExist(
django.template.base.VariableDoesNotExist: Failed lookup for key [image] in {'item': 'concrete_calculator', 'location': 'https://tdleningrad.ru/service/calc/', 'lastmod': datetime.datetime(2025, 3, 18, 21, 26, 18, 969505), 'changefreq': 'daily', 'priority': '0.8', 'alternates': []}
DEBUG 2025-03-18 21:26:19,085 base Exception while resolving variable 'image' in template 'sitemap_with_images.xml'.
Traceback (most recent call last):
  File "/home/igor/venv/lib/python3.10/site-packages/django/template/base.py", line 880, in _resolve_lookup
    current = current[bit]
KeyError: 'image'

During handling of the above exception, another exception occurred:

Traceback (most recent call last):
  File "/home/igor/venv/lib/python3.10/site-packages/django/template/base.py", line 890, in _resolve_lookup
    current = getattr(current, bit)
AttributeError: 'dict' object has no attribute 'image'

During handling of the above exception, another exception occurred:

Traceback (most recent call last):
  File "/home/igor/venv/lib/python3.10/site-packages/django/template/base.py", line 896, in _resolve_lookup
    current = current[int(bit)]
ValueError: invalid literal for int() with base 10: 'image'

During handling of the above exception, another exception occurred:

Traceback (most recent call last):
  File "/home/igor/venv/lib/python3.10/site-packages/django/template/base.py", line 903, in _resolve_lookup
    raise VariableDoesNotExist(
django.template.base.VariableDoesNotExist: Failed lookup for key [image] in {'item': <Product: Бетон М400>, 'location': 'https://tdleningrad.ru/catalog/donetsk/beton/donetsk-beton-m400/', 'lastmod': datetime.datetime(2025, 3, 5, 19, 55, 0, 861995, tzinfo=datetime.timezone.utc), 'changefreq': 'daily', 'priority': '0.7', 'alternates': []}
DEBUG 2025-03-18 21:26:19,085 base Exception while resolving variable 'image' in template 'sitemap_with_images.xml'.
Traceback (most recent call last):
  File "/home/igor/venv/lib/python3.10/site-packages/django/template/base.py", line 880, in _resolve_lookup
    current = current[bit]
KeyError: 'image'

During handling of the above exception, another exception occurred:

Traceback (most recent call last):
  File "/home/igor/venv/lib/python3.10/site-packages/django/template/base.py", line 890, in _resolve_lookup
    current = getattr(current, bit)
AttributeError: 'dict' object has no attribute 'image'

During handling of the above exception, another exception occurred:

Traceback (most recent call last):
  File "/home/igor/venv/lib/python3.10/site-packages/django/template/base.py", line 896, in _resolve_lookup
    current = current[int(bit)]
ValueError: invalid literal for int() with base 10: 'image'

During handling of the above exception, another exception occurred:

Traceback (most recent call last):
  File "/home/igor/venv/lib/python3.10/site-packages/django/template/base.py", line 903, in _resolve_lookup
    raise VariableDoesNotExist(
django.template.base.VariableDoesNotExist: Failed lookup for key [image] in {'item': <Product: Бетон М300>, 'location': 'https://tdleningrad.ru/catalog/donetsk/beton/donetsk-beton-m300/', 'lastmod': datetime.datetime(2025, 3, 5, 19, 55, 14, 637909, tzinfo=datetime.timezone.utc), 'changefreq': 'daily', 'priority': '0.7', 'alternates': []}
DEBUG 2025-03-18 21:26:19,086 base Exception while resolving variable 'image' in template 'sitemap_with_images.xml'.
Traceback (most recent call last):
  File "/home/igor/venv/lib/python3.10/site-packages/django/template/base.py", line 880, in _resolve_lookup
    current = current[bit]
KeyError: 'image'

During handling of the above exception, another exception occurred:

Traceback (most recent call last):
  File "/home/igor/venv/lib/python3.10/site-packages/django/template/base.py", line 890, in _resolve_lookup
    current = getattr(current, bit)
AttributeError: 'dict' object has no attribute 'image'

During handling of the above exception, another exception occurred:

Traceback (most recent call last):
  File "/home/igor/venv/lib/python3.10/site-packages/django/template/base.py", line 896, in _resolve_lookup
    current = current[int(bit)]
ValueError: invalid literal for int() with base 10: 'image'

During handling of the above exception, another exception occurred:

Traceback (most recent call last):
  File "/home/igor/venv/lib/python3.10/site-packages/django/template/base.py", line 903, in _resolve_lookup
    raise VariableDoesNotExist(
django.template.base.VariableDoesNotExist: Failed lookup for key [image] in {'item': <Product: Бетон М250>, 'location': 'https://tdleningrad.ru/catalog/donetsk/beton/donetsk-beton-m250/', 'lastmod': datetime.datetime(2025, 3, 5, 19, 55, 33, 218668, tzinfo=datetime.timezone.utc), 'changefreq': 'daily', 'priority': '0.7', 'alternates': []}
DEBUG 2025-03-18 21:26:19,087 base Exception while resolving variable 'image' in template 'sitemap_with_images.xml'.
Traceback (most recent call last):
  File "/home/igor/venv/lib/python3.10/site-packages/django/template/base.py", line 880, in _resolve_lookup
    current = current[bit]
KeyError: 'image'

During handling of the above exception, another exception occurred:

Traceback (most recent call last):
  File "/home/igor/venv/lib/python3.10/site-packages/django/template/base.py", line 890, in _resolve_lookup
    current = getattr(current, bit)
AttributeError: 'dict' object has no attribute 'image'

During handling of the above exception, another exception occurred:

Traceback (most recent call last):
  File "/home/igor/venv/lib/python3.10/site-packages/django/template/base.py", line 896, in _resolve_lookup
    current = current[int(bit)]
ValueError: invalid literal for int() with base 10: 'image'

During handling of the above exception, another exception occurred:

Traceback (most recent call last):
  File "/home/igor/venv/lib/python3.10/site-packages/django/template/base.py", line 903, in _resolve_lookup
    raise VariableDoesNotExist(
django.template.base.VariableDoesNotExist: Failed lookup for key [image] in {'item': <Product: Бетон М200>, 'location': 'https://tdleningrad.ru/catalog/donetsk/beton/donetsk-beton-m200/', 'lastmod': datetime.datetime(2025, 3, 5, 19, 55, 49, 428891, tzinfo=datetime.timezone.utc), 'changefreq': 'daily', 'priority': '0.7', 'alternates': []}
DEBUG 2025-03-18 21:26:19,087 base Exception while resolving variable 'image' in template 'sitemap_with_images.xml'.
Traceback (most recent call last):
  File "/home/igor/venv/lib/python3.10/site-packages/django/template/base.py", line 880, in _resolve_lookup
    current = current[bit]
KeyError: 'image'

During handling of the above exception, another exception occurred:

Traceback (most recent call last):
  File "/home/igor/venv/lib/python3.10/site-packages/django/template/base.py", line 890, in _resolve_lookup
    current = getattr(current, bit)
AttributeError: 'dict' object has no attribute 'image'

During handling of the above exception, another exception occurred:

Traceback (most recent call last):
  File "/home/igor/venv/lib/python3.10/site-packages/django/template/base.py", line 896, in _resolve_lookup
    current = current[int(bit)]
ValueError: invalid literal for int() with base 10: 'image'

During handling of the above exception, another exception occurred:

Traceback (most recent call last):
  File "/home/igor/venv/lib/python3.10/site-packages/django/template/base.py", line 903, in _resolve_lookup
    raise VariableDoesNotExist(
django.template.base.VariableDoesNotExist: Failed lookup for key [image] in {'item': <Product: Бетон М100>, 'location': 'https://tdleningrad.ru/catalog/donetsk/beton/donetsk-beton-m100/', 'lastmod': datetime.datetime(2025, 3, 5, 19, 56, 15, 125275, tzinfo=datetime.timezone.utc), 'changefreq': 'daily', 'priority': '0.7', 'alternates': []}
DEBUG 2025-03-18 21:26:19,088 base Exception while resolving variable 'image' in template 'sitemap_with_images.xml'.
Traceback (most recent call last):
  File "/home/igor/venv/lib/python3.10/site-packages/django/template/base.py", line 880, in _resolve_lookup
    current = current[bit]
KeyError: 'image'

During handling of the above exception, another exception occurred:

Traceback (most recent call last):
  File "/home/igor/venv/lib/python3.10/site-packages/django/template/base.py", line 890, in _resolve_lookup
    current = getattr(current, bit)
AttributeError: 'dict' object has no attribute 'image'

During handling of the above exception, another exception occurred:

Traceback (most recent call last):
  File "/home/igor/venv/lib/python3.10/site-packages/django/template/base.py", line 896, in _resolve_lookup
    current = current[int(bit)]
ValueError: invalid literal for int() with base 10: 'image'

During handling of the above exception, another exception occurred:

Traceback (most recent call last):
  File "/home/igor/venv/lib/python3.10/site-packages/django/template/base.py", line 903, in _resolve_lookup
    raise VariableDoesNotExist(
django.template.base.VariableDoesNotExist: Failed lookup for key [image] in {'item': <Product: Бетон М50>, 'location': 'https://tdleningrad.ru/catalog/donetsk/beton/donetsk-beton-m50/', 'lastmod': datetime.datetime(2025, 3, 5, 19, 56, 25, 18132, tzinfo=datetime.timezone.utc), 'changefreq': 'daily', 'priority': '0.7', 'alternates': []}
DEBUG 2025-03-18 21:26:19,088 base Exception while resolving variable 'image' in template 'sitemap_with_images.xml'.
Traceback (most recent call last):
  File "/home/igor/venv/lib/python3.10/site-packages/django/template/base.py", line 880, in _resolve_lookup
    current = current[bit]
KeyError: 'image'

During handling of the above exception, another exception occurred:

Traceback (most recent call last):
  File "/home/igor/venv/lib/python3.10/site-packages/django/template/base.py", line 890, in _resolve_lookup
    current = getattr(current, bit)
AttributeError: 'dict' object has no attribute 'image'

During handling of the above exception, another exception occurred:

Traceback (most recent call last):
  File "/home/igor/venv/lib/python3.10/site-packages/django/template/base.py", line 896, in _resolve_lookup
    current = current[int(bit)]
ValueError: invalid literal for int() with base 10: 'image'

During handling of the above exception, another exception occurred:

Traceback (most recent call last):
  File "/home/igor/venv/lib/python3.10/site-packages/django/template/base.py", line 903, in _resolve_lookup
    raise VariableDoesNotExist(
django.template.base.VariableDoesNotExist: Failed lookup for key [image] in {'item': <Product: Строительный песок>, 'location': 'https://tdleningrad.ru/catalog/donetsk/pesok/donetsk-pesok/', 'lastmod': datetime.datetime(2025, 3, 5, 19, 56, 39, 246003, tzinfo=datetime.timezone.utc), 'changefreq': 'daily', 'priority': '0.7', 'alternates': []}
DEBUG 2025-03-18 21:26:19,089 base Exception while resolving variable 'image' in template 'sitemap_with_images.xml'.
Traceback (most recent call last):
  File "/home/igor/venv/lib/python3.10/site-packages/django/template/base.py", line 880, in _resolve_lookup
    current = current[bit]
KeyError: 'image'

During handling of the above exception, another exception occurred:

Traceback (most recent call last):
  File "/home/igor/venv/lib/python3.10/site-packages/django/template/base.py", line 890, in _resolve_lookup
    current = getattr(current, bit)
AttributeError: 'dict' object has no attribute 'image'

During handling of the above exception, another exception occurred:

Traceback (most recent call last):
  File "/home/igor/venv/lib/python3.10/site-packages/django/template/base.py", line 896, in _resolve_lookup
    current = current[int(bit)]
ValueError: invalid literal for int() with base 10: 'image'

During handling of the above exception, another exception occurred:

Traceback (most recent call last):
  File "/home/igor/venv/lib/python3.10/site-packages/django/template/base.py", line 903, in _resolve_lookup
    raise VariableDoesNotExist(
django.template.base.VariableDoesNotExist: Failed lookup for key [image] in {'item': <Product: Гранитный щебень 20-40>, 'location': 'https://tdleningrad.ru/catalog/lugansk/sheben/lugansk-sheben-20-40/', 'lastmod': datetime.datetime(2025, 3, 5, 20, 2, 2, 446514, tzinfo=datetime.timezone.utc), 'changefreq': 'daily', 'priority': '0.7', 'alternates': []}
DEBUG 2025-03-18 21:26:19,089 base Exception while resolving variable 'image' in template 'sitemap_with_images.xml'.
Traceback (most recent call last):
  File "/home/igor/venv/lib/python3.10/site-packages/django/template/base.py", line 880, in _resolve_lookup
    current = current[bit]
KeyError: 'image'

During handling of the above exception, another exception occurred:

Traceback (most recent call last):
  File "/home/igor/venv/lib/python3.10/site-packages/django/template/base.py", line 890, in _resolve_lookup
    current = getattr(current, bit)
AttributeError: 'dict' object has no attribute 'image'

During handling of the above exception, another exception occurred:

Traceback (most recent call last):
  File "/home/igor/venv/lib/python3.10/site-packages/django/template/base.py", line 896, in _resolve_lookup
    current = current[int(bit)]
ValueError: invalid literal for int() with base 10: 'image'

During handling of the above exception, another exception occurred:

Traceback (most recent call last):
  File "/home/igor/venv/lib/python3.10/site-packages/django/template/base.py", line 903, in _resolve_lookup
    raise VariableDoesNotExist(
django.template.base.VariableDoesNotExist: Failed lookup for key [image] in {'item': <Product: Гранитный щебень 10-20>, 'location': 'https://tdleningrad.ru/catalog/lugansk/sheben/lugansk-sheben-10-20/', 'lastmod': datetime.datetime(2025, 3, 5, 20, 1, 52, 744999, tzinfo=datetime.timezone.utc), 'changefreq': 'daily', 'priority': '0.7', 'alternates': []}
DEBUG 2025-03-18 21:26:19,090 base Exception while resolving variable 'image' in template 'sitemap_with_images.xml'.
Traceback (most recent call last):
  File "/home/igor/venv/lib/python3.10/site-packages/django/template/base.py", line 880, in _resolve_lookup
    current = current[bit]
KeyError: 'image'

During handling of the above exception, another exception occurred:

Traceback (most recent call last):
  File "/home/igor/venv/lib/python3.10/site-packages/django/template/base.py", line 890, in _resolve_lookup
    current = getattr(current, bit)
AttributeError: 'dict' object has no attribute 'image'

During handling of the above exception, another exception occurred:

Traceback (most recent call last):
  File "/home/igor/venv/lib/python3.10/site-packages/django/template/base.py", line 896, in _resolve_lookup
    current = current[int(bit)]
ValueError: invalid literal for int() with base 10: 'image'

During handling of the above exception, another exception occurred:

Traceback (most recent call last):
  File "/home/igor/venv/lib/python3.10/site-packages/django/template/base.py", line 903, in _resolve_lookup
    raise VariableDoesNotExist(
django.template.base.VariableDoesNotExist: Failed lookup for key [image] in {'item': <Product: Асфальт тип Б марка 1 крупнозернистый плотный>, 'location': 'https://tdleningrad.ru/catalog/mariupol/asfalt/mariupol-asfalt-tip-b/', 'lastmod': datetime.datetime(2025, 3, 5, 20, 0, 29, 314903, tzinfo=datetime.timezone.utc), 'changefreq': 'daily', 'priority': '0.7', 'alternates': []}
DEBUG 2025-03-18 21:26:19,091 base Exception while resolving variable 'image' in template 'sitemap_with_images.xml'.
Traceback (most recent call last):
  File "/home/igor/venv/lib/python3.10/site-packages/django/template/base.py", line 880, in _resolve_lookup
    current = current[bit]
KeyError: 'image'

During handling of the above exception, another exception occurred:

Traceback (most recent call last):
  File "/home/igor/venv/lib/python3.10/site-packages/django/template/base.py", line 890, in _resolve_lookup
    current = getattr(current, bit)
AttributeError: 'dict' object has no attribute 'image'

During handling of the above exception, another exception occurred:

Traceback (most recent call last):
  File "/home/igor/venv/lib/python3.10/site-packages/django/template/base.py", line 896, in _resolve_lookup
    current = current[int(bit)]
ValueError: invalid literal for int() with base 10: 'image'

During handling of the above exception, another exception occurred:

Traceback (most recent call last):
  File "/home/igor/venv/lib/python3.10/site-packages/django/template/base.py", line 903, in _resolve_lookup
    raise VariableDoesNotExist(
django.template.base.VariableDoesNotExist: Failed lookup for key [image] in {'item': <Product: Гранитный щебень 20-40>, 'location': 'https://tdleningrad.ru/catalog/donetsk/sheben/sheben-donetsk-20-40/', 'lastmod': datetime.datetime(2025, 3, 5, 19, 57, 27, 687674, tzinfo=datetime.timezone.utc), 'changefreq': 'daily', 'priority': '0.7', 'alternates': []}
DEBUG 2025-03-18 21:26:19,091 base Exception while resolving variable 'image' in template 'sitemap_with_images.xml'.
Traceback (most recent call last):
  File "/home/igor/venv/lib/python3.10/site-packages/django/template/base.py", line 880, in _resolve_lookup
    current = current[bit]
KeyError: 'image'

During handling of the above exception, another exception occurred:

Traceback (most recent call last):
  File "/home/igor/venv/lib/python3.10/site-packages/django/template/base.py", line 890, in _resolve_lookup
    current = getattr(current, bit)
AttributeError: 'dict' object has no attribute 'image'

During handling of the above exception, another exception occurred:

Traceback (most recent call last):
  File "/home/igor/venv/lib/python3.10/site-packages/django/template/base.py", line 896, in _resolve_lookup
    current = current[int(bit)]
ValueError: invalid literal for int() with base 10: 'image'

During handling of the above exception, another exception occurred:

Traceback (most recent call last):
  File "/home/igor/venv/lib/python3.10/site-packages/django/template/base.py", line 903, in _resolve_lookup
    raise VariableDoesNotExist(
django.template.base.VariableDoesNotExist: Failed lookup for key [image] in {'item': <Product: Гранитный щебень 10-20>, 'location': 'https://tdleningrad.ru/catalog/donetsk/sheben/sheben-donetsk-10-20/', 'lastmod': datetime.datetime(2025, 3, 5, 19, 57, 12, 204465, tzinfo=datetime.timezone.utc), 'changefreq': 'daily', 'priority': '0.7', 'alternates': []}
DEBUG 2025-03-18 21:26:19,092 base Exception while resolving variable 'image' in template 'sitemap_with_images.xml'.
Traceback (most recent call last):
  File "/home/igor/venv/lib/python3.10/site-packages/django/template/base.py", line 880, in _resolve_lookup
    current = current[bit]
KeyError: 'image'

During handling of the above exception, another exception occurred:

Traceback (most recent call last):
  File "/home/igor/venv/lib/python3.10/site-packages/django/template/base.py", line 890, in _resolve_lookup
    current = getattr(current, bit)
AttributeError: 'dict' object has no attribute 'image'

During handling of the above exception, another exception occurred:

Traceback (most recent call last):
  File "/home/igor/venv/lib/python3.10/site-packages/django/template/base.py", line 896, in _resolve_lookup
    current = current[int(bit)]
ValueError: invalid literal for int() with base 10: 'image'

During handling of the above exception, another exception occurred:

Traceback (most recent call last):
  File "/home/igor/venv/lib/python3.10/site-packages/django/template/base.py", line 903, in _resolve_lookup
    raise VariableDoesNotExist(
django.template.base.VariableDoesNotExist: Failed lookup for key [image] in {'item': <Product: Гранитный щебень 5-10>, 'location': 'https://tdleningrad.ru/catalog/donetsk/sheben/sheben-donetsk-5-10/', 'lastmod': datetime.datetime(2025, 3, 5, 19, 57, 18, 781461, tzinfo=datetime.timezone.utc), 'changefreq': 'daily', 'priority': '0.7', 'alternates': []}
DEBUG 2025-03-18 21:26:19,092 base Exception while resolving variable 'image' in template 'sitemap_with_images.xml'.
Traceback (most recent call last):
  File "/home/igor/venv/lib/python3.10/site-packages/django/template/base.py", line 880, in _resolve_lookup
    current = current[bit]
KeyError: 'image'

During handling of the above exception, another exception occurred:

Traceback (most recent call last):
  File "/home/igor/venv/lib/python3.10/site-packages/django/template/base.py", line 890, in _resolve_lookup
    current = getattr(current, bit)
AttributeError: 'dict' object has no attribute 'image'

During handling of the above exception, another exception occurred:

Traceback (most recent call last):
  File "/home/igor/venv/lib/python3.10/site-packages/django/template/base.py", line 896, in _resolve_lookup
    current = current[int(bit)]
ValueError: invalid literal for int() with base 10: 'image'

During handling of the above exception, another exception occurred:

Traceback (most recent call last):
  File "/home/igor/venv/lib/python3.10/site-packages/django/template/base.py", line 903, in _resolve_lookup
    raise VariableDoesNotExist(
django.template.base.VariableDoesNotExist: Failed lookup for key [image] in {'item': <Product: Гранитный щебень 20-40>, 'location': 'https://tdleningrad.ru/catalog/mariupol/sheben/sheben-20-40/', 'lastmod': datetime.datetime(2025, 3, 5, 20, 0, 16, 776035, tzinfo=datetime.timezone.utc), 'changefreq': 'daily', 'priority': '0.7', 'alternates': []}
DEBUG 2025-03-18 21:26:19,093 base Exception while resolving variable 'image' in template 'sitemap_with_images.xml'.
Traceback (most recent call last):
  File "/home/igor/venv/lib/python3.10/site-packages/django/template/base.py", line 880, in _resolve_lookup
    current = current[bit]
KeyError: 'image'

During handling of the above exception, another exception occurred:

Traceback (most recent call last):
  File "/home/igor/venv/lib/python3.10/site-packages/django/template/base.py", line 890, in _resolve_lookup
    current = getattr(current, bit)
AttributeError: 'dict' object has no attribute 'image'

During handling of the above exception, another exception occurred:

Traceback (most recent call last):
  File "/home/igor/venv/lib/python3.10/site-packages/django/template/base.py", line 896, in _resolve_lookup
    current = current[int(bit)]
ValueError: invalid literal for int() with base 10: 'image'

During handling of the above exception, another exception occurred:

Traceback (most recent call last):
  File "/home/igor/venv/lib/python3.10/site-packages/django/template/base.py", line 903, in _resolve_lookup
    raise VariableDoesNotExist(
django.template.base.VariableDoesNotExist: Failed lookup for key [image] in {'item': <Product: Гранитный щебень 10-20>, 'location': 'https://tdleningrad.ru/catalog/mariupol/sheben/sheben-10-20/', 'lastmod': datetime.datetime(2025, 3, 5, 20, 0, 7, 118916, tzinfo=datetime.timezone.utc), 'changefreq': 'daily', 'priority': '0.7', 'alternates': []}
DEBUG 2025-03-18 21:26:19,093 base Exception while resolving variable 'image' in template 'sitemap_with_images.xml'.
Traceback (most recent call last):
  File "/home/igor/venv/lib/python3.10/site-packages/django/template/base.py", line 880, in _resolve_lookup
    current = current[bit]
KeyError: 'image'

During handling of the above exception, another exception occurred:

Traceback (most recent call last):
  File "/home/igor/venv/lib/python3.10/site-packages/django/template/base.py", line 890, in _resolve_lookup
    current = getattr(current, bit)
AttributeError: 'dict' object has no attribute 'image'

During handling of the above exception, another exception occurred:

Traceback (most recent call last):
  File "/home/igor/venv/lib/python3.10/site-packages/django/template/base.py", line 896, in _resolve_lookup
    current = current[int(bit)]
ValueError: invalid literal for int() with base 10: 'image'

During handling of the above exception, another exception occurred:

Traceback (most recent call last):
  File "/home/igor/venv/lib/python3.10/site-packages/django/template/base.py", line 903, in _resolve_lookup
    raise VariableDoesNotExist(
django.template.base.VariableDoesNotExist: Failed lookup for key [image] in {'item': <Product: Гранитный щебень 5-10>, 'location': 'https://tdleningrad.ru/catalog/mariupol/sheben/sheben-5-10/', 'lastmod': datetime.datetime(2025, 3, 5, 19, 59, 58, 441860, tzinfo=datetime.timezone.utc), 'changefreq': 'daily', 'priority': '0.7', 'alternates': []}
DEBUG 2025-03-18 21:26:19,094 base Exception while resolving variable 'image' in template 'sitemap_with_images.xml'.
Traceback (most recent call last):
  File "/home/igor/venv/lib/python3.10/site-packages/django/template/base.py", line 880, in _resolve_lookup
    current = current[bit]
KeyError: 'image'

During handling of the above exception, another exception occurred:

Traceback (most recent call last):
  File "/home/igor/venv/lib/python3.10/site-packages/django/template/base.py", line 890, in _resolve_lookup
    current = getattr(current, bit)
AttributeError: 'dict' object has no attribute 'image'

During handling of the above exception, another exception occurred:

Traceback (most recent call last):
  File "/home/igor/venv/lib/python3.10/site-packages/django/template/base.py", line 896, in _resolve_lookup
    current = current[int(bit)]
ValueError: invalid literal for int() with base 10: 'image'

During handling of the above exception, another exception occurred:

Traceback (most recent call last):
  File "/home/igor/venv/lib/python3.10/site-packages/django/template/base.py", line 903, in _resolve_lookup
    raise VariableDoesNotExist(
django.template.base.VariableDoesNotExist: Failed lookup for key [image] in {'item': <Product: Строительный песок>, 'location': 'https://tdleningrad.ru/catalog/lugansk/pesok/stroitelnyj-pesok/', 'lastmod': datetime.datetime(2025, 3, 5, 20, 0, 55, 584928, tzinfo=datetime.timezone.utc), 'changefreq': 'daily', 'priority': '0.7', 'alternates': []}
DEBUG 2025-03-18 21:26:19,095 base Exception while resolving variable 'image' in template 'sitemap_with_images.xml'.
Traceback (most recent call last):
  File "/home/igor/venv/lib/python3.10/site-packages/django/template/base.py", line 880, in _resolve_lookup
    current = current[bit]
KeyError: 'image'

During handling of the above exception, another exception occurred:

Traceback (most recent call last):
  File "/home/igor/venv/lib/python3.10/site-packages/django/template/base.py", line 890, in _resolve_lookup
    current = getattr(current, bit)
AttributeError: 'dict' object has no attribute 'image'

During handling of the above exception, another exception occurred:

Traceback (most recent call last):
  File "/home/igor/venv/lib/python3.10/site-packages/django/template/base.py", line 896, in _resolve_lookup
    current = current[int(bit)]
ValueError: invalid literal for int() with base 10: 'image'

During handling of the above exception, another exception occurred:

Traceback (most recent call last):
  File "/home/igor/venv/lib/python3.10/site-packages/django/template/base.py", line 903, in _resolve_lookup
    raise VariableDoesNotExist(
django.template.base.VariableDoesNotExist: Failed lookup for key [image] in {'item': <Product: Асфальт тип Б марка 1 крупнозернистый плотный>, 'location': 'https://tdleningrad.ru/catalog/lugansk/asfalt/asfalt-b-1/', 'lastmod': datetime.datetime(2025, 3, 5, 20, 0, 43, 478310, tzinfo=datetime.timezone.utc), 'changefreq': 'daily', 'priority': '0.7', 'alternates': []}
DEBUG 2025-03-18 21:26:19,095 base Exception while resolving variable 'image' in template 'sitemap_with_images.xml'.
Traceback (most recent call last):
  File "/home/igor/venv/lib/python3.10/site-packages/django/template/base.py", line 880, in _resolve_lookup
    current = current[bit]
KeyError: 'image'

During handling of the above exception, another exception occurred:

Traceback (most recent call last):
  File "/home/igor/venv/lib/python3.10/site-packages/django/template/base.py", line 890, in _resolve_lookup
    current = getattr(current, bit)
AttributeError: 'dict' object has no attribute 'image'

During handling of the above exception, another exception occurred:

Traceback (most recent call last):
  File "/home/igor/venv/lib/python3.10/site-packages/django/template/base.py", line 896, in _resolve_lookup
    current = current[int(bit)]
ValueError: invalid literal for int() with base 10: 'image'

During handling of the above exception, another exception occurred:

Traceback (most recent call last):
  File "/home/igor/venv/lib/python3.10/site-packages/django/template/base.py", line 903, in _resolve_lookup
    raise VariableDoesNotExist(
django.template.base.VariableDoesNotExist: Failed lookup for key [image] in {'item': <Product: Гранитный щебень 5-10>, 'location': 'https://tdleningrad.ru/catalog/lugansk/sheben/lugansk-sheben-5-10/', 'lastmod': datetime.datetime(2025, 3, 5, 20, 1, 43, 58448, tzinfo=datetime.timezone.utc), 'changefreq': 'daily', 'priority': '0.7', 'alternates': []}
DEBUG 2025-03-18 21:26:19,096 base Exception while resolving variable 'image' in template 'sitemap_with_images.xml'.
Traceback (most recent call last):
  File "/home/igor/venv/lib/python3.10/site-packages/django/template/base.py", line 880, in _resolve_lookup
    current = current[bit]
KeyError: 'image'

During handling of the above exception, another exception occurred:

Traceback (most recent call last):
  File "/home/igor/venv/lib/python3.10/site-packages/django/template/base.py", line 890, in _resolve_lookup
    current = getattr(current, bit)
AttributeError: 'dict' object has no attribute 'image'

During handling of the above exception, another exception occurred:

Traceback (most recent call last):
  File "/home/igor/venv/lib/python3.10/site-packages/django/template/base.py", line 896, in _resolve_lookup
    current = current[int(bit)]
ValueError: invalid literal for int() with base 10: 'image'

During handling of the above exception, another exception occurred:

Traceback (most recent call last):
  File "/home/igor/venv/lib/python3.10/site-packages/django/template/base.py", line 903, in _resolve_lookup
    raise VariableDoesNotExist(
django.template.base.VariableDoesNotExist: Failed lookup for key [image] in {'item': <Product: Бетон М400>, 'location': 'https://tdleningrad.ru/catalog/mariupol/beton/beton-m400/', 'lastmod': datetime.datetime(2025, 3, 5, 19, 59, 42, 803245, tzinfo=datetime.timezone.utc), 'changefreq': 'daily', 'priority': '0.7', 'alternates': []}
DEBUG 2025-03-18 21:26:19,096 base Exception while resolving variable 'image' in template 'sitemap_with_images.xml'.
Traceback (most recent call last):
  File "/home/igor/venv/lib/python3.10/site-packages/django/template/base.py", line 880, in _resolve_lookup
    current = current[bit]
KeyError: 'image'

During handling of the above exception, another exception occurred:

Traceback (most recent call last):
  File "/home/igor/venv/lib/python3.10/site-packages/django/template/base.py", line 890, in _resolve_lookup
    current = getattr(current, bit)
AttributeError: 'dict' object has no attribute 'image'

During handling of the above exception, another exception occurred:

Traceback (most recent call last):
  File "/home/igor/venv/lib/python3.10/site-packages/django/template/base.py", line 896, in _resolve_lookup
    current = current[int(bit)]
ValueError: invalid literal for int() with base 10: 'image'

During handling of the above exception, another exception occurred:

Traceback (most recent call last):
  File "/home/igor/venv/lib/python3.10/site-packages/django/template/base.py", line 903, in _resolve_lookup
    raise VariableDoesNotExist(
django.template.base.VariableDoesNotExist: Failed lookup for key [image] in {'item': <Product: Бетон М300>, 'location': 'https://tdleningrad.ru/catalog/mariupol/beton/beton-m300/', 'lastmod': datetime.datetime(2025, 3, 5, 19, 59, 33, 377090, tzinfo=datetime.timezone.utc), 'changefreq': 'daily', 'priority': '0.7', 'alternates': []}
DEBUG 2025-03-18 21:26:19,097 base Exception while resolving variable 'image' in template 'sitemap_with_images.xml'.
Traceback (most recent call last):
  File "/home/igor/venv/lib/python3.10/site-packages/django/template/base.py", line 880, in _resolve_lookup
    current = current[bit]
KeyError: 'image'

During handling of the above exception, another exception occurred:

Traceback (most recent call last):
  File "/home/igor/venv/lib/python3.10/site-packages/django/template/base.py", line 890, in _resolve_lookup
    current = getattr(current, bit)
AttributeError: 'dict' object has no attribute 'image'

During handling of the above exception, another exception occurred:

Traceback (most recent call last):
  File "/home/igor/venv/lib/python3.10/site-packages/django/template/base.py", line 896, in _resolve_lookup
    current = current[int(bit)]
ValueError: invalid literal for int() with base 10: 'image'

During handling of the above exception, another exception occurred:

Traceback (most recent call last):
  File "/home/igor/venv/lib/python3.10/site-packages/django/template/base.py", line 903, in _resolve_lookup
    raise VariableDoesNotExist(
django.template.base.VariableDoesNotExist: Failed lookup for key [image] in {'item': <Product: Бетон М250>, 'location': 'https://tdleningrad.ru/catalog/mariupol/beton/beton-m250/', 'lastmod': datetime.datetime(2025, 3, 5, 19, 59, 18, 274707, tzinfo=datetime.timezone.utc), 'changefreq': 'daily', 'priority': '0.7', 'alternates': []}
DEBUG 2025-03-18 21:26:19,097 base Exception while resolving variable 'image' in template 'sitemap_with_images.xml'.
Traceback (most recent call last):
  File "/home/igor/venv/lib/python3.10/site-packages/django/template/base.py", line 880, in _resolve_lookup
    current = current[bit]
KeyError: 'image'

During handling of the above exception, another exception occurred:

Traceback (most recent call last):
  File "/home/igor/venv/lib/python3.10/site-packages/django/template/base.py", line 890, in _resolve_lookup
    current = getattr(current, bit)
AttributeError: 'dict' object has no attribute 'image'

During handling of the above exception, another exception occurred:

Traceback (most recent call last):
  File "/home/igor/venv/lib/python3.10/site-packages/django/template/base.py", line 896, in _resolve_lookup
    current = current[int(bit)]
ValueError: invalid literal for int() with base 10: 'image'

During handling of the above exception, another exception occurred:

Traceback (most recent call last):
  File "/home/igor/venv/lib/python3.10/site-packages/django/template/base.py", line 903, in _resolve_lookup
    raise VariableDoesNotExist(
django.template.base.VariableDoesNotExist: Failed lookup for key [image] in {'item': <Product: Бетон М200>, 'location': 'https://tdleningrad.ru/catalog/mariupol/beton/beton-m200/', 'lastmod': datetime.datetime(2025, 3, 5, 19, 59, 9, 930380, tzinfo=datetime.timezone.utc), 'changefreq': 'daily', 'priority': '0.7', 'alternates': []}
DEBUG 2025-03-18 21:26:19,098 base Exception while resolving variable 'image' in template 'sitemap_with_images.xml'.
Traceback (most recent call last):
  File "/home/igor/venv/lib/python3.10/site-packages/django/template/base.py", line 880, in _resolve_lookup
    current = current[bit]
KeyError: 'image'

During handling of the above exception, another exception occurred:

Traceback (most recent call last):
  File "/home/igor/venv/lib/python3.10/site-packages/django/template/base.py", line 890, in _resolve_lookup
    current = getattr(current, bit)
AttributeError: 'dict' object has no attribute 'image'

During handling of the above exception, another exception occurred:

Traceback (most recent call last):
  File "/home/igor/venv/lib/python3.10/site-packages/django/template/base.py", line 896, in _resolve_lookup
    current = current[int(bit)]
ValueError: invalid literal for int() with base 10: 'image'

During handling of the above exception, another exception occurred:

Traceback (most recent call last):
  File "/home/igor/venv/lib/python3.10/site-packages/django/template/base.py", line 903, in _resolve_lookup
    raise VariableDoesNotExist(
django.template.base.VariableDoesNotExist: Failed lookup for key [image] in {'item': <Product: Бетон М50>, 'location': 'https://tdleningrad.ru/catalog/mariupol/beton/beton-m50/', 'lastmod': datetime.datetime(2025, 3, 5, 19, 58, 50, 527772, tzinfo=datetime.timezone.utc), 'changefreq': 'daily', 'priority': '0.7', 'alternates': []}
DEBUG 2025-03-18 21:26:19,100 base Exception while resolving variable 'image' in template 'sitemap_with_images.xml'.
Traceback (most recent call last):
  File "/home/igor/venv/lib/python3.10/site-packages/django/template/base.py", line 880, in _resolve_lookup
    current = current[bit]
KeyError: 'image'

During handling of the above exception, another exception occurred:

Traceback (most recent call last):
  File "/home/igor/venv/lib/python3.10/site-packages/django/template/base.py", line 890, in _resolve_lookup
    current = getattr(current, bit)
AttributeError: 'dict' object has no attribute 'image'

During handling of the above exception, another exception occurred:

Traceback (most recent call last):
  File "/home/igor/venv/lib/python3.10/site-packages/django/template/base.py", line 896, in _resolve_lookup
    current = current[int(bit)]
ValueError: invalid literal for int() with base 10: 'image'

During handling of the above exception, another exception occurred:

Traceback (most recent call last):
  File "/home/igor/venv/lib/python3.10/site-packages/django/template/base.py", line 903, in _resolve_lookup
    raise VariableDoesNotExist(
django.template.base.VariableDoesNotExist: Failed lookup for key [image] in {'item': <Product: Бетон М100>, 'location': 'https://tdleningrad.ru/catalog/mariupol/beton/beton-m100/', 'lastmod': datetime.datetime(2025, 3, 5, 19, 58, 59, 715012, tzinfo=datetime.timezone.utc), 'changefreq': 'daily', 'priority': '0.7', 'alternates': []}
DEBUG 2025-03-18 21:26:19,100 base Exception while resolving variable 'image' in template 'sitemap_with_images.xml'.
Traceback (most recent call last):
  File "/home/igor/venv/lib/python3.10/site-packages/django/template/base.py", line 880, in _resolve_lookup
    current = current[bit]
KeyError: 'image'

During handling of the above exception, another exception occurred:

Traceback (most recent call last):
  File "/home/igor/venv/lib/python3.10/site-packages/django/template/base.py", line 890, in _resolve_lookup
    current = getattr(current, bit)
AttributeError: 'dict' object has no attribute 'image'

During handling of the above exception, another exception occurred:

Traceback (most recent call last):
  File "/home/igor/venv/lib/python3.10/site-packages/django/template/base.py", line 896, in _resolve_lookup
    current = current[int(bit)]
ValueError: invalid literal for int() with base 10: 'image'

During handling of the above exception, another exception occurred:

Traceback (most recent call last):
  File "/home/igor/venv/lib/python3.10/site-packages/django/template/base.py", line 903, in _resolve_lookup
    raise VariableDoesNotExist(
django.template.base.VariableDoesNotExist: Failed lookup for key [image] in {'item': (<City: Донецк>, <Category: Бетон>), 'location': 'https://tdleningrad.ru/catalog/donetsk/beton/', 'lastmod': datetime.datetime(2025, 3, 5, 19, 56, 25, 18132, tzinfo=datetime.timezone.utc), 'changefreq': 'weekly', 'priority': '0.6', 'alternates': []}
DEBUG 2025-03-18 21:26:19,101 base Exception while resolving variable 'image' in template 'sitemap_with_images.xml'.
Traceback (most recent call last):
  File "/home/igor/venv/lib/python3.10/site-packages/django/template/base.py", line 880, in _resolve_lookup
    current = current[bit]
KeyError: 'image'

During handling of the above exception, another exception occurred:

Traceback (most recent call last):
  File "/home/igor/venv/lib/python3.10/site-packages/django/template/base.py", line 890, in _resolve_lookup
    current = getattr(current, bit)
AttributeError: 'dict' object has no attribute 'image'

During handling of the above exception, another exception occurred:

Traceback (most recent call last):
  File "/home/igor/venv/lib/python3.10/site-packages/django/template/base.py", line 896, in _resolve_lookup
    current = current[int(bit)]
ValueError: invalid literal for int() with base 10: 'image'

During handling of the above exception, another exception occurred:

Traceback (most recent call last):
  File "/home/igor/venv/lib/python3.10/site-packages/django/template/base.py", line 903, in _resolve_lookup
    raise VariableDoesNotExist(
django.template.base.VariableDoesNotExist: Failed lookup for key [image] in {'item': (<City: Донецк>, <Category: Песок>), 'location': 'https://tdleningrad.ru/catalog/donetsk/pesok/', 'lastmod': datetime.datetime(2025, 3, 5, 19, 56, 39, 246003, tzinfo=datetime.timezone.utc), 'changefreq': 'weekly', 'priority': '0.6', 'alternates': []}
DEBUG 2025-03-18 21:26:19,101 base Exception while resolving variable 'image' in template 'sitemap_with_images.xml'.
Traceback (most recent call last):
  File "/home/igor/venv/lib/python3.10/site-packages/django/template/base.py", line 880, in _resolve_lookup
    current = current[bit]
KeyError: 'image'

During handling of the above exception, another exception occurred:

Traceback (most recent call last):
  File "/home/igor/venv/lib/python3.10/site-packages/django/template/base.py", line 890, in _resolve_lookup
    current = getattr(current, bit)
AttributeError: 'dict' object has no attribute 'image'

During handling of the above exception, another exception occurred:

Traceback (most recent call last):
  File "/home/igor/venv/lib/python3.10/site-packages/django/template/base.py", line 896, in _resolve_lookup
    current = current[int(bit)]
ValueError: invalid literal for int() with base 10: 'image'

During handling of the above exception, another exception occurred:

Traceback (most recent call last):
  File "/home/igor/venv/lib/python3.10/site-packages/django/template/base.py", line 903, in _resolve_lookup
    raise VariableDoesNotExist(
django.template.base.VariableDoesNotExist: Failed lookup for key [image] in {'item': (<City: Донецк>, <Category: Щебень>), 'location': 'https://tdleningrad.ru/catalog/donetsk/sheben/', 'lastmod': datetime.datetime(2025, 3, 5, 19, 57, 27, 687674, tzinfo=datetime.timezone.utc), 'changefreq': 'weekly', 'priority': '0.6', 'alternates': []}
DEBUG 2025-03-18 21:26:19,102 base Exception while resolving variable 'image' in template 'sitemap_with_images.xml'.
Traceback (most recent call last):
  File "/home/igor/venv/lib/python3.10/site-packages/django/template/base.py", line 880, in _resolve_lookup
    current = current[bit]
KeyError: 'image'

During handling of the above exception, another exception occurred:

Traceback (most recent call last):
  File "/home/igor/venv/lib/python3.10/site-packages/django/template/base.py", line 890, in _resolve_lookup
    current = getattr(current, bit)
AttributeError: 'dict' object has no attribute 'image'

During handling of the above exception, another exception occurred:

Traceback (most recent call last):
  File "/home/igor/venv/lib/python3.10/site-packages/django/template/base.py", line 896, in _resolve_lookup
    current = current[int(bit)]
ValueError: invalid literal for int() with base 10: 'image'

During handling of the above exception, another exception occurred:

Traceback (most recent call last):
  File "/home/igor/venv/lib/python3.10/site-packages/django/template/base.py", line 903, in _resolve_lookup
    raise VariableDoesNotExist(
django.template.base.VariableDoesNotExist: Failed lookup for key [image] in {'item': (<City: Мариуполь>, <Category: Бетон>), 'location': 'https://tdleningrad.ru/catalog/mariupol/beton/', 'lastmod': datetime.datetime(2025, 3, 5, 19, 59, 42, 803245, tzinfo=datetime.timezone.utc), 'changefreq': 'weekly', 'priority': '0.6', 'alternates': []}
DEBUG 2025-03-18 21:26:19,103 base Exception while resolving variable 'image' in template 'sitemap_with_images.xml'.
Traceback (most recent call last):
  File "/home/igor/venv/lib/python3.10/site-packages/django/template/base.py", line 880, in _resolve_lookup
    current = current[bit]
KeyError: 'image'

During handling of the above exception, another exception occurred:

Traceback (most recent call last):
  File "/home/igor/venv/lib/python3.10/site-packages/django/template/base.py", line 890, in _resolve_lookup
    current = getattr(current, bit)
AttributeError: 'dict' object has no attribute 'image'

During handling of the above exception, another exception occurred:

Traceback (most recent call last):
  File "/home/igor/venv/lib/python3.10/site-packages/django/template/base.py", line 896, in _resolve_lookup
    current = current[int(bit)]
ValueError: invalid literal for int() with base 10: 'image'

During handling of the above exception, another exception occurred:

Traceback (most recent call last):
  File "/home/igor/venv/lib/python3.10/site-packages/django/template/base.py", line 903, in _resolve_lookup
    raise VariableDoesNotExist(
django.template.base.VariableDoesNotExist: Failed lookup for key [image] in {'item': (<City: Мариуполь>, <Category: Щебень>), 'location': 'https://tdleningrad.ru/catalog/mariupol/sheben/', 'lastmod': datetime.datetime(2025, 3, 5, 20, 0, 16, 776035, tzinfo=datetime.timezone.utc), 'changefreq': 'weekly', 'priority': '0.6', 'alternates': []}
DEBUG 2025-03-18 21:26:19,103 base Exception while resolving variable 'image' in template 'sitemap_with_images.xml'.
Traceback (most recent call last):
  File "/home/igor/venv/lib/python3.10/site-packages/django/template/base.py", line 880, in _resolve_lookup
    current = current[bit]
KeyError: 'image'

During handling of the above exception, another exception occurred:

Traceback (most recent call last):
  File "/home/igor/venv/lib/python3.10/site-packages/django/template/base.py", line 890, in _resolve_lookup
    current = getattr(current, bit)
AttributeError: 'dict' object has no attribute 'image'

During handling of the above exception, another exception occurred:

Traceback (most recent call last):
  File "/home/igor/venv/lib/python3.10/site-packages/django/template/base.py", line 896, in _resolve_lookup
    current = current[int(bit)]
ValueError: invalid literal for int() with base 10: 'image'

During handling of the above exception, another exception occurred:

Traceback (most recent call last):
  File "/home/igor/venv/lib/python3.10/site-packages/django/template/base.py", line 903, in _resolve_lookup
    raise VariableDoesNotExist(
django.template.base.VariableDoesNotExist: Failed lookup for key [image] in {'item': (<City: Мариуполь>, <Category: Асфальт>), 'location': 'https://tdleningrad.ru/catalog/mariupol/asfalt/', 'lastmod': datetime.datetime(2025, 3, 5, 20, 0, 29, 314903, tzinfo=datetime.timezone.utc), 'changefreq': 'weekly', 'priority': '0.6', 'alternates': []}
DEBUG 2025-03-18 21:26:19,104 base Exception while resolving variable 'image' in template 'sitemap_with_images.xml'.
Traceback (most recent call last):
  File "/home/igor/venv/lib/python3.10/site-packages/django/template/base.py", line 880, in _resolve_lookup
    current = current[bit]
KeyError: 'image'

During handling of the above exception, another exception occurred:

Traceback (most recent call last):
  File "/home/igor/venv/lib/python3.10/site-packages/django/template/base.py", line 890, in _resolve_lookup
    current = getattr(current, bit)
AttributeError: 'dict' object has no attribute 'image'

During handling of the above exception, another exception occurred:

Traceback (most recent call last):
  File "/home/igor/venv/lib/python3.10/site-packages/django/template/base.py", line 896, in _resolve_lookup
    current = current[int(bit)]
ValueError: invalid literal for int() with base 10: 'image'

During handling of the above exception, another exception occurred:

Traceback (most recent call last):
  File "/home/igor/venv/lib/python3.10/site-packages/django/template/base.py", line 903, in _resolve_lookup
    raise VariableDoesNotExist(
django.template.base.VariableDoesNotExist: Failed lookup for key [image] in {'item': (<City: Луганск>, <Category: Песок>), 'location': 'https://tdleningrad.ru/catalog/lugansk/pesok/', 'lastmod': datetime.datetime(2025, 3, 5, 20, 0, 55, 584928, tzinfo=datetime.timezone.utc), 'changefreq': 'weekly', 'priority': '0.6', 'alternates': []}
DEBUG 2025-03-18 21:26:19,104 base Exception while resolving variable 'image' in template 'sitemap_with_images.xml'.
Traceback (most recent call last):
  File "/home/igor/venv/lib/python3.10/site-packages/django/template/base.py", line 880, in _resolve_lookup
    current = current[bit]
KeyError: 'image'

During handling of the above exception, another exception occurred:

Traceback (most recent call last):
  File "/home/igor/venv/lib/python3.10/site-packages/django/template/base.py", line 890, in _resolve_lookup
    current = getattr(current, bit)
AttributeError: 'dict' object has no attribute 'image'

During handling of the above exception, another exception occurred:

Traceback (most recent call last):
  File "/home/igor/venv/lib/python3.10/site-packages/django/template/base.py", line 896, in _resolve_lookup
    current = current[int(bit)]
ValueError: invalid literal for int() with base 10: 'image'

During handling of the above exception, another exception occurred:

Traceback (most recent call last):
  File "/home/igor/venv/lib/python3.10/site-packages/django/template/base.py", line 903, in _resolve_lookup
    raise VariableDoesNotExist(
django.template.base.VariableDoesNotExist: Failed lookup for key [image] in {'item': (<City: Луганск>, <Category: Щебень>), 'location': 'https://tdleningrad.ru/catalog/lugansk/sheben/', 'lastmod': datetime.datetime(2025, 3, 5, 20, 2, 2, 446514, tzinfo=datetime.timezone.utc), 'changefreq': 'weekly', 'priority': '0.6', 'alternates': []}
DEBUG 2025-03-18 21:26:19,105 base Exception while resolving variable 'image' in template 'sitemap_with_images.xml'.
Traceback (most recent call last):
  File "/home/igor/venv/lib/python3.10/site-packages/django/template/base.py", line 880, in _resolve_lookup
    current = current[bit]
KeyError: 'image'

During handling of the above exception, another exception occurred:

Traceback (most recent call last):
  File "/home/igor/venv/lib/python3.10/site-packages/django/template/base.py", line 890, in _resolve_lookup
    current = getattr(current, bit)
AttributeError: 'dict' object has no attribute 'image'

During handling of the above exception, another exception occurred:

Traceback (most recent call last):
  File "/home/igor/venv/lib/python3.10/site-packages/django/template/base.py", line 896, in _resolve_lookup
    current = current[int(bit)]
ValueError: invalid literal for int() with base 10: 'image'

During handling of the above exception, another exception occurred:

Traceback (most recent call last):
  File "/home/igor/venv/lib/python3.10/site-packages/django/template/base.py", line 903, in _resolve_lookup
    raise VariableDoesNotExist(
django.template.base.VariableDoesNotExist: Failed lookup for key [image] in {'item': (<City: Луганск>, <Category: Асфальт>), 'location': 'https://tdleningrad.ru/catalog/lugansk/asfalt/', 'lastmod': datetime.datetime(2025, 3, 5, 20, 0, 43, 478310, tzinfo=datetime.timezone.utc), 'changefreq': 'weekly', 'priority': '0.6', 'alternates': []}
DEBUG 2025-03-18 21:26:19,105 base Exception while resolving variable 'image' in template 'sitemap_with_images.xml'.
Traceback (most recent call last):
  File "/home/igor/venv/lib/python3.10/site-packages/django/template/base.py", line 880, in _resolve_lookup
    current = current[bit]
KeyError: 'image'

During handling of the above exception, another exception occurred:

Traceback (most recent call last):
  File "/home/igor/venv/lib/python3.10/site-packages/django/template/base.py", line 890, in _resolve_lookup
    current = getattr(current, bit)
AttributeError: 'dict' object has no attribute 'image'

During handling of the above exception, another exception occurred:

Traceback (most recent call last):
  File "/home/igor/venv/lib/python3.10/site-packages/django/template/base.py", line 896, in _resolve_lookup
    current = current[int(bit)]
ValueError: invalid literal for int() with base 10: 'image'

During handling of the above exception, another exception occurred:

Traceback (most recent call last):
  File "/home/igor/venv/lib/python3.10/site-packages/django/template/base.py", line 903, in _resolve_lookup
    raise VariableDoesNotExist(
django.template.base.VariableDoesNotExist: Failed lookup for key [image] in {'item': <City: Мариуполь>, 'location': 'https://tdleningrad.ru/catalog/mariupol/', 'lastmod': datetime.datetime(2025, 3, 5, 20, 0, 29, 314903, tzinfo=datetime.timezone.utc), 'changefreq': 'weekly', 'priority': '0.6', 'alternates': []}
DEBUG 2025-03-18 21:26:19,106 base Exception while resolving variable 'image' in template 'sitemap_with_images.xml'.
Traceback (most recent call last):
  File "/home/igor/venv/lib/python3.10/site-packages/django/template/base.py", line 880, in _resolve_lookup
    current = current[bit]
KeyError: 'image'

During handling of the above exception, another exception occurred:

Traceback (most recent call last):
  File "/home/igor/venv/lib/python3.10/site-packages/django/template/base.py", line 890, in _resolve_lookup
    current = getattr(current, bit)
AttributeError: 'dict' object has no attribute 'image'

During handling of the above exception, another exception occurred:

Traceback (most recent call last):
  File "/home/igor/venv/lib/python3.10/site-packages/django/template/base.py", line 896, in _resolve_lookup
    current = current[int(bit)]
ValueError: invalid literal for int() with base 10: 'image'

During handling of the above exception, another exception occurred:

Traceback (most recent call last):
  File "/home/igor/venv/lib/python3.10/site-packages/django/template/base.py", line 903, in _resolve_lookup
    raise VariableDoesNotExist(
django.template.base.VariableDoesNotExist: Failed lookup for key [image] in {'item': <City: Луганск>, 'location': 'https://tdleningrad.ru/catalog/lugansk/', 'lastmod': datetime.datetime(2025, 3, 5, 20, 2, 2, 446514, tzinfo=datetime.timezone.utc), 'changefreq': 'weekly', 'priority': '0.6', 'alternates': []}
DEBUG 2025-03-18 21:26:19,106 base Exception while resolving variable 'image' in template 'sitemap_with_images.xml'.
Traceback (most recent call last):
  File "/home/igor/venv/lib/python3.10/site-packages/django/template/base.py", line 880, in _resolve_lookup
    current = current[bit]
KeyError: 'image'

During handling of the above exception, another exception occurred:

Traceback (most recent call last):
  File "/home/igor/venv/lib/python3.10/site-packages/django/template/base.py", line 890, in _resolve_lookup
    current = getattr(current, bit)
AttributeError: 'dict' object has no attribute 'image'

During handling of the above exception, another exception occurred:

Traceback (most recent call last):
  File "/home/igor/venv/lib/python3.10/site-packages/django/template/base.py", line 896, in _resolve_lookup
    current = current[int(bit)]
ValueError: invalid literal for int() with base 10: 'image'

During handling of the above exception, another exception occurred:

Traceback (most recent call last):
  File "/home/igor/venv/lib/python3.10/site-packages/django/template/base.py", line 903, in _resolve_lookup
    raise VariableDoesNotExist(
django.template.base.VariableDoesNotExist: Failed lookup for key [image] in {'item': <City: Донецк>, 'location': 'https://tdleningrad.ru/catalog/donetsk/', 'lastmod': datetime.datetime(2025, 3, 5, 19, 57, 27, 687674, tzinfo=datetime.timezone.utc), 'changefreq': 'weekly', 'priority': '0.6', 'alternates': []}
